[2019-11-18 08:57:09,420] [basehttp.py:124] [basehttp:log_message] [INFO]- "POST /v1/users/user HTTP/1.1" 200 80
[2019-11-18 08:57:11,279] [basehttp.py:124] [basehttp:log_message] [INFO]- "POST /v1/users/user HTTP/1.1" 200 80
[2019-11-18 08:57:18,860] [basehttp.py:124] [basehttp:log_message] [INFO]- "POST /v1/users/user HTTP/1.1" 200 86
[2019-11-18 08:57:22,129] [basehttp.py:124] [basehttp:log_message] [INFO]- "POST /v1/users/user HTTP/1.1" 200 86
[2019-11-18 08:57:23,051] [basehttp.py:124] [basehttp:log_message] [INFO]- "POST /v1/users/user HTTP/1.1" 200 86
[2019-11-18 09:05:35,621] [exception.py:135] [exception:handle_uncaught_exception] [ERROR]- Internal Server Error: /v1/users/user
Traceback (most recent call last):
  File "/home/tarena/.local/lib/python3.6/site-packages/django/core/handlers/exception.py", line 41, in inner
    response = get_response(request)
  File "/home/tarena/.local/lib/python3.6/site-packages/django/core/handlers/base.py", line 187, in _get_response
    response = self.process_exception_by_middleware(e, request)
  File "/home/tarena/.local/lib/python3.6/site-packages/django/core/handlers/base.py", line 185, in _get_response
    response = wrapped_callback(request, *callback_args, **callback_kwargs)
  File "/home/tarena/.local/lib/python3.6/site-packages/django/views/generic/base.py", line 68, in view
    return self.dispatch(request, *args, **kwargs)
  File "/home/tarena/.local/lib/python3.6/site-packages/django/views/generic/base.py", line 88, in dispatch
    return handler(request, *args, **kwargs)
  File "/home/tarena/桌面/git/Storage/storage/users/views.py", line 25, in get
    return JsonResponse(LinqHelper.res_format(code, res))
  File "/home/tarena/桌面/git/Storage/storage/common/LinqHelper.py", line 27, in res_format
    for model_itme in list(list_msg.values()):
AttributeError: 'Paginator' object has no attribute 'values'
[2019-11-18 09:05:35,679] [basehttp.py:124] [basehttp:log_message] [ERROR]- "GET /v1/users/user?page=1 HTTP/1.1" 500 86288
[2019-11-18 09:08:00,070] [exception.py:135] [exception:handle_uncaught_exception] [ERROR]- Internal Server Error: /v1/users/user
Traceback (most recent call last):
  File "/home/tarena/.local/lib/python3.6/site-packages/django/core/handlers/exception.py", line 41, in inner
    response = get_response(request)
  File "/home/tarena/.local/lib/python3.6/site-packages/django/core/handlers/base.py", line 187, in _get_response
    response = self.process_exception_by_middleware(e, request)
  File "/home/tarena/.local/lib/python3.6/site-packages/django/core/handlers/base.py", line 185, in _get_response
    response = wrapped_callback(request, *callback_args, **callback_kwargs)
  File "/home/tarena/.local/lib/python3.6/site-packages/django/views/generic/base.py", line 68, in view
    return self.dispatch(request, *args, **kwargs)
  File "/home/tarena/.local/lib/python3.6/site-packages/django/views/generic/base.py", line 88, in dispatch
    return handler(request, *args, **kwargs)
  File "/home/tarena/桌面/git/Storage/storage/users/views.py", line 23, in get
    code, res = LinqHelper.db_finds(lambda: Paginator(TUser.objects.filter(), 10))
AttributeError: type object 'LinqHelper' has no attribute 'db_finds'
[2019-11-18 09:08:00,116] [basehttp.py:124] [basehttp:log_message] [ERROR]- "GET /v1/users/user?page=1 HTTP/1.1" 500 81451
[2019-11-18 09:08:07,368] [exception.py:135] [exception:handle_uncaught_exception] [ERROR]- Internal Server Error: /v1/users/user
Traceback (most recent call last):
  File "/home/tarena/.local/lib/python3.6/site-packages/django/core/handlers/exception.py", line 41, in inner
    response = get_response(request)
  File "/home/tarena/.local/lib/python3.6/site-packages/django/core/handlers/base.py", line 187, in _get_response
    response = self.process_exception_by_middleware(e, request)
  File "/home/tarena/.local/lib/python3.6/site-packages/django/core/handlers/base.py", line 185, in _get_response
    response = wrapped_callback(request, *callback_args, **callback_kwargs)
  File "/home/tarena/.local/lib/python3.6/site-packages/django/views/generic/base.py", line 68, in view
    return self.dispatch(request, *args, **kwargs)
  File "/home/tarena/.local/lib/python3.6/site-packages/django/views/generic/base.py", line 88, in dispatch
    return handler(request, *args, **kwargs)
  File "/home/tarena/桌面/git/Storage/storage/users/views.py", line 23, in get
    code, res = LinqHelper.db_finds(lambda: Paginator(TUser.objects.filter(), 10))
AttributeError: type object 'LinqHelper' has no attribute 'db_finds'
[2019-11-18 09:08:07,427] [basehttp.py:124] [basehttp:log_message] [ERROR]- "GET /v1/users/user?page=1 HTTP/1.1" 500 81451
[2019-11-18 09:08:11,679] [exception.py:135] [exception:handle_uncaught_exception] [ERROR]- Internal Server Error: /v1/users/user
Traceback (most recent call last):
  File "/home/tarena/.local/lib/python3.6/site-packages/django/core/handlers/exception.py", line 41, in inner
    response = get_response(request)
  File "/home/tarena/.local/lib/python3.6/site-packages/django/core/handlers/base.py", line 187, in _get_response
    response = self.process_exception_by_middleware(e, request)
  File "/home/tarena/.local/lib/python3.6/site-packages/django/core/handlers/base.py", line 185, in _get_response
    response = wrapped_callback(request, *callback_args, **callback_kwargs)
  File "/home/tarena/.local/lib/python3.6/site-packages/django/views/generic/base.py", line 68, in view
    return self.dispatch(request, *args, **kwargs)
  File "/home/tarena/.local/lib/python3.6/site-packages/django/views/generic/base.py", line 88, in dispatch
    return handler(request, *args, **kwargs)
  File "/home/tarena/桌面/git/Storage/storage/users/views.py", line 23, in get
    code, res = LinqHelper.db_finds(lambda: Paginator(TUser.objects.filter(), 10))
AttributeError: type object 'LinqHelper' has no attribute 'db_finds'
[2019-11-18 09:08:11,719] [basehttp.py:124] [basehttp:log_message] [ERROR]- "GET /v1/users/user?page=1 HTTP/1.1" 500 81451
[2019-11-18 09:08:47,194] [exception.py:135] [exception:handle_uncaught_exception] [ERROR]- Internal Server Error: /v1/users/user
Traceback (most recent call last):
  File "/home/tarena/.local/lib/python3.6/site-packages/django/core/handlers/exception.py", line 41, in inner
    response = get_response(request)
  File "/home/tarena/.local/lib/python3.6/site-packages/django/core/handlers/base.py", line 187, in _get_response
    response = self.process_exception_by_middleware(e, request)
  File "/home/tarena/.local/lib/python3.6/site-packages/django/core/handlers/base.py", line 185, in _get_response
    response = wrapped_callback(request, *callback_args, **callback_kwargs)
  File "/home/tarena/.local/lib/python3.6/site-packages/django/views/generic/base.py", line 68, in view
    return self.dispatch(request, *args, **kwargs)
  File "/home/tarena/.local/lib/python3.6/site-packages/django/views/generic/base.py", line 88, in dispatch
    return handler(request, *args, **kwargs)
  File "/home/tarena/桌面/git/Storage/storage/users/views.py", line 23, in get
    elif page:
AttributeError: type object 'LinqHelper' has no attribute 'db_finds'
[2019-11-18 09:08:47,244] [basehttp.py:124] [basehttp:log_message] [ERROR]- "GET /v1/users/user?page=1 HTTP/1.1" 500 81302
[2019-11-18 09:09:28,384] [exception.py:135] [exception:handle_uncaught_exception] [ERROR]- Internal Server Error: /v1/users/user
Traceback (most recent call last):
  File "/home/tarena/.local/lib/python3.6/site-packages/django/core/handlers/exception.py", line 41, in inner
    response = get_response(request)
  File "/home/tarena/.local/lib/python3.6/site-packages/django/core/handlers/base.py", line 187, in _get_response
    response = self.process_exception_by_middleware(e, request)
  File "/home/tarena/.local/lib/python3.6/site-packages/django/core/handlers/base.py", line 185, in _get_response
    response = wrapped_callback(request, *callback_args, **callback_kwargs)
  File "/home/tarena/.local/lib/python3.6/site-packages/django/views/generic/base.py", line 68, in view
    return self.dispatch(request, *args, **kwargs)
  File "/home/tarena/.local/lib/python3.6/site-packages/django/views/generic/base.py", line 88, in dispatch
    return handler(request, *args, **kwargs)
  File "/home/tarena/桌面/git/Storage/storage/users/views.py", line 26, in get
    return JsonResponse(LinqHelper.res_format(code, res))
  File "/home/tarena/桌面/git/Storage/storage/common/LinqHelper.py", line 26, in res_format
    for model_itme in list(list_msg.values()):
AttributeError: 'Paginator' object has no attribute 'values'
[2019-11-18 09:09:28,435] [basehttp.py:124] [basehttp:log_message] [ERROR]- "GET /v1/users/user?page=1 HTTP/1.1" 500 86289
[2019-11-18 09:14:36,569] [basehttp.py:124] [basehttp:log_message] [INFO]- "GET /v1/users/user?page=1 HTTP/1.1" 200 2
[2019-11-18 09:14:52,400] [basehttp.py:124] [basehttp:log_message] [INFO]- "GET /v1/users/user?page=1 HTTP/1.1" 200 2
[2019-11-18 09:15:13,129] [exception.py:135] [exception:handle_uncaught_exception] [ERROR]- Internal Server Error: /v1/users/user
Traceback (most recent call last):
  File "/home/tarena/.local/lib/python3.6/site-packages/django/core/handlers/exception.py", line 41, in inner
    response = get_response(request)
  File "/home/tarena/.local/lib/python3.6/site-packages/django/core/handlers/base.py", line 187, in _get_response
    response = self.process_exception_by_middleware(e, request)
  File "/home/tarena/.local/lib/python3.6/site-packages/django/core/handlers/base.py", line 185, in _get_response
    response = wrapped_callback(request, *callback_args, **callback_kwargs)
  File "/home/tarena/.local/lib/python3.6/site-packages/django/views/generic/base.py", line 68, in view
    return self.dispatch(request, *args, **kwargs)
  File "/home/tarena/.local/lib/python3.6/site-packages/django/views/generic/base.py", line 88, in dispatch
    return handler(request, *args, **kwargs)
  File "/home/tarena/桌面/git/Storage/storage/users/views.py", line 27, in get
    for i in data:
TypeError: 'Paginator' object is not iterable
[2019-11-18 09:15:13,180] [basehttp.py:124] [basehttp:log_message] [ERROR]- "GET /v1/users/user?page=1 HTTP/1.1" 500 81514
[2019-11-18 09:15:52,057] [exception.py:135] [exception:handle_uncaught_exception] [ERROR]- Internal Server Error: /v1/users/user
Traceback (most recent call last):
  File "/home/tarena/.local/lib/python3.6/site-packages/django/core/handlers/exception.py", line 41, in inner
    response = get_response(request)
  File "/home/tarena/.local/lib/python3.6/site-packages/django/core/handlers/base.py", line 187, in _get_response
    response = self.process_exception_by_middleware(e, request)
  File "/home/tarena/.local/lib/python3.6/site-packages/django/core/handlers/base.py", line 185, in _get_response
    response = wrapped_callback(request, *callback_args, **callback_kwargs)
  File "/home/tarena/.local/lib/python3.6/site-packages/django/views/generic/base.py", line 68, in view
    return self.dispatch(request, *args, **kwargs)
  File "/home/tarena/.local/lib/python3.6/site-packages/django/views/generic/base.py", line 88, in dispatch
    return handler(request, *args, **kwargs)
  File "/home/tarena/桌面/git/Storage/storage/users/views.py", line 29, in get
    for i in data:
TypeError: 'Paginator' object is not iterable
[2019-11-18 09:15:52,106] [basehttp.py:124] [basehttp:log_message] [ERROR]- "GET /v1/users/user?page=1 HTTP/1.1" 500 81512
[2019-11-18 09:16:57,587] [exception.py:135] [exception:handle_uncaught_exception] [ERROR]- Internal Server Error: /v1/users/user
Traceback (most recent call last):
  File "/home/tarena/.local/lib/python3.6/site-packages/django/core/handlers/exception.py", line 41, in inner
    response = get_response(request)
  File "/home/tarena/.local/lib/python3.6/site-packages/django/core/handlers/base.py", line 187, in _get_response
    response = self.process_exception_by_middleware(e, request)
  File "/home/tarena/.local/lib/python3.6/site-packages/django/core/handlers/base.py", line 185, in _get_response
    response = wrapped_callback(request, *callback_args, **callback_kwargs)
  File "/home/tarena/.local/lib/python3.6/site-packages/django/views/generic/base.py", line 68, in view
    return self.dispatch(request, *args, **kwargs)
  File "/home/tarena/.local/lib/python3.6/site-packages/django/views/generic/base.py", line 88, in dispatch
    return handler(request, *args, **kwargs)
  File "/home/tarena/桌面/git/Storage/storage/users/views.py", line 27, in get
    print(data.number)
AttributeError: 'Paginator' object has no attribute 'number'
[2019-11-18 09:16:57,636] [basehttp.py:124] [basehttp:log_message] [ERROR]- "GET /v1/users/user?page=1 HTTP/1.1" 500 81635
[2019-11-18 09:17:08,792] [exception.py:135] [exception:handle_uncaught_exception] [ERROR]- Internal Server Error: /v1/users/user
Traceback (most recent call last):
  File "/home/tarena/.local/lib/python3.6/site-packages/django/core/handlers/exception.py", line 41, in inner
    response = get_response(request)
  File "/home/tarena/.local/lib/python3.6/site-packages/django/core/handlers/base.py", line 187, in _get_response
    response = self.process_exception_by_middleware(e, request)
  File "/home/tarena/.local/lib/python3.6/site-packages/django/core/handlers/base.py", line 185, in _get_response
    response = wrapped_callback(request, *callback_args, **callback_kwargs)
  File "/home/tarena/.local/lib/python3.6/site-packages/django/views/generic/base.py", line 68, in view
    return self.dispatch(request, *args, **kwargs)
  File "/home/tarena/.local/lib/python3.6/site-packages/django/views/generic/base.py", line 88, in dispatch
    return handler(request, *args, **kwargs)
  File "/home/tarena/桌面/git/Storage/storage/users/views.py", line 27, in get
    print(data.number)
AttributeError: 'Paginator' object has no attribute 'number'
[2019-11-18 09:17:08,831] [basehttp.py:124] [basehttp:log_message] [ERROR]- "GET /v1/users/user?page=1 HTTP/1.1" 500 81635
[2019-11-18 09:17:30,508] [exception.py:135] [exception:handle_uncaught_exception] [ERROR]- Internal Server Error: /v1/users/user
Traceback (most recent call last):
  File "/home/tarena/.local/lib/python3.6/site-packages/django/core/handlers/exception.py", line 41, in inner
    response = get_response(request)
  File "/home/tarena/.local/lib/python3.6/site-packages/django/core/handlers/base.py", line 187, in _get_response
    response = self.process_exception_by_middleware(e, request)
  File "/home/tarena/.local/lib/python3.6/site-packages/django/core/handlers/base.py", line 185, in _get_response
    response = wrapped_callback(request, *callback_args, **callback_kwargs)
  File "/home/tarena/.local/lib/python3.6/site-packages/django/views/generic/base.py", line 68, in view
    return self.dispatch(request, *args, **kwargs)
  File "/home/tarena/.local/lib/python3.6/site-packages/django/views/generic/base.py", line 88, in dispatch
    return handler(request, *args, **kwargs)
  File "/home/tarena/桌面/git/Storage/storage/users/views.py", line 31, in get
    for i in data:
TypeError: 'Paginator' object is not iterable
[2019-11-18 09:17:30,560] [basehttp.py:124] [basehttp:log_message] [ERROR]- "GET /v1/users/user?page=1 HTTP/1.1" 500 81459
[2019-11-18 09:18:41,065] [exception.py:135] [exception:handle_uncaught_exception] [ERROR]- Internal Server Error: /v1/users/user
Traceback (most recent call last):
  File "/home/tarena/.local/lib/python3.6/site-packages/django/core/handlers/exception.py", line 41, in inner
    response = get_response(request)
  File "/home/tarena/.local/lib/python3.6/site-packages/django/core/handlers/base.py", line 187, in _get_response
    response = self.process_exception_by_middleware(e, request)
  File "/home/tarena/.local/lib/python3.6/site-packages/django/core/handlers/base.py", line 185, in _get_response
    response = wrapped_callback(request, *callback_args, **callback_kwargs)
  File "/home/tarena/.local/lib/python3.6/site-packages/django/views/generic/base.py", line 68, in view
    return self.dispatch(request, *args, **kwargs)
  File "/home/tarena/.local/lib/python3.6/site-packages/django/views/generic/base.py", line 88, in dispatch
    return handler(request, *args, **kwargs)
  File "/home/tarena/桌面/git/Storage/storage/users/views.py", line 33, in get
    for i in data:
TypeError: 'Paginator' object is not iterable
[2019-11-18 09:18:41,117] [basehttp.py:124] [basehttp:log_message] [ERROR]- "GET /v1/users/user?page=1 HTTP/1.1" 500 81682
[2019-11-18 09:18:47,338] [exception.py:135] [exception:handle_uncaught_exception] [ERROR]- Internal Server Error: /v1/users/user
Traceback (most recent call last):
  File "/home/tarena/.local/lib/python3.6/site-packages/django/core/handlers/exception.py", line 41, in inner
    response = get_response(request)
  File "/home/tarena/.local/lib/python3.6/site-packages/django/core/handlers/base.py", line 187, in _get_response
    response = self.process_exception_by_middleware(e, request)
  File "/home/tarena/.local/lib/python3.6/site-packages/django/core/handlers/base.py", line 185, in _get_response
    response = wrapped_callback(request, *callback_args, **callback_kwargs)
  File "/home/tarena/.local/lib/python3.6/site-packages/django/views/generic/base.py", line 68, in view
    return self.dispatch(request, *args, **kwargs)
  File "/home/tarena/.local/lib/python3.6/site-packages/django/views/generic/base.py", line 88, in dispatch
    return handler(request, *args, **kwargs)
  File "/home/tarena/桌面/git/Storage/storage/users/views.py", line 33, in get
    for i in data:
TypeError: 'Paginator' object is not iterable
[2019-11-18 09:18:47,381] [basehttp.py:124] [basehttp:log_message] [ERROR]- "GET /v1/users/user?page=1 HTTP/1.1" 500 81682
[2019-11-18 09:19:03,905] [basehttp.py:124] [basehttp:log_message] [INFO]- "GET /v1/users/user?page=1 HTTP/1.1" 200 2
[2019-11-18 09:19:37,513] [exception.py:135] [exception:handle_uncaught_exception] [ERROR]- Internal Server Error: /v1/users/user
Traceback (most recent call last):
  File "/home/tarena/.local/lib/python3.6/site-packages/django/core/handlers/exception.py", line 41, in inner
    response = get_response(request)
  File "/home/tarena/.local/lib/python3.6/site-packages/django/core/handlers/base.py", line 187, in _get_response
    response = self.process_exception_by_middleware(e, request)
  File "/home/tarena/.local/lib/python3.6/site-packages/django/core/handlers/base.py", line 185, in _get_response
    response = wrapped_callback(request, *callback_args, **callback_kwargs)
  File "/home/tarena/.local/lib/python3.6/site-packages/django/views/generic/base.py", line 68, in view
    return self.dispatch(request, *args, **kwargs)
  File "/home/tarena/.local/lib/python3.6/site-packages/django/views/generic/base.py", line 88, in dispatch
    return handler(request, *args, **kwargs)
  File "/home/tarena/桌面/git/Storage/storage/users/views.py", line 33, in get
    return JsonResponse(res)
  File "/home/tarena/.local/lib/python3.6/site-packages/django/http/response.py", line 530, in __init__
    data = json.dumps(data, cls=encoder, **json_dumps_params)
  File "/usr/lib/python3.6/json/__init__.py", line 238, in dumps
    **kw).encode(obj)
  File "/usr/lib/python3.6/json/encoder.py", line 199, in encode
    chunks = self.iterencode(o, _one_shot=True)
  File "/usr/lib/python3.6/json/encoder.py", line 257, in iterencode
    return _iterencode(o, 0)
  File "/home/tarena/.local/lib/python3.6/site-packages/django/core/serializers/json.py", line 124, in default
    return super(DjangoJSONEncoder, self).default(o)
  File "/usr/lib/python3.6/json/encoder.py", line 180, in default
    o.__class__.__name__)
TypeError: Object of type 'QuerySet' is not JSON serializable
[2019-11-18 09:19:37,619] [basehttp.py:124] [basehttp:log_message] [ERROR]- "GET /v1/users/user?page=1 HTTP/1.1" 500 107837
[2019-11-18 09:20:11,839] [exception.py:135] [exception:handle_uncaught_exception] [ERROR]- Internal Server Error: /v1/users/user
Traceback (most recent call last):
  File "/home/tarena/.local/lib/python3.6/site-packages/django/core/handlers/exception.py", line 41, in inner
    response = get_response(request)
  File "/home/tarena/.local/lib/python3.6/site-packages/django/core/handlers/base.py", line 187, in _get_response
    response = self.process_exception_by_middleware(e, request)
  File "/home/tarena/.local/lib/python3.6/site-packages/django/core/handlers/base.py", line 185, in _get_response
    response = wrapped_callback(request, *callback_args, **callback_kwargs)
  File "/home/tarena/.local/lib/python3.6/site-packages/django/views/generic/base.py", line 68, in view
    return self.dispatch(request, *args, **kwargs)
  File "/home/tarena/.local/lib/python3.6/site-packages/django/views/generic/base.py", line 88, in dispatch
    return handler(request, *args, **kwargs)
  File "/home/tarena/桌面/git/Storage/storage/users/views.py", line 26, in get
    res = {'data': LinqHelper.res_format(lambda: data.object_list)}
TypeError: res_format() missing 1 required positional argument: 'list_msg'
[2019-11-18 09:20:11,886] [basehttp.py:124] [basehttp:log_message] [ERROR]- "GET /v1/users/user?page=1 HTTP/1.1" 500 81801
[2019-11-18 09:20:54,448] [basehttp.py:124] [basehttp:log_message] [INFO]- "GET /v1/users/user?page=1 HTTP/1.1" 200 226
[2019-11-18 09:21:17,625] [basehttp.py:124] [basehttp:log_message] [INFO]- "POST /v1/users/user HTTP/1.1" 200 86
[2019-11-18 09:21:19,854] [basehttp.py:124] [basehttp:log_message] [INFO]- "POST /v1/users/user HTTP/1.1" 200 86
[2019-11-18 09:21:21,283] [basehttp.py:124] [basehttp:log_message] [INFO]- "POST /v1/users/user HTTP/1.1" 200 86
[2019-11-18 09:21:22,772] [basehttp.py:124] [basehttp:log_message] [INFO]- "POST /v1/users/user HTTP/1.1" 200 86
[2019-11-18 09:21:28,031] [basehttp.py:124] [basehttp:log_message] [INFO]- "POST /v1/users/user HTTP/1.1" 200 86
[2019-11-18 09:21:38,716] [basehttp.py:124] [basehttp:log_message] [INFO]- "POST /v1/users/user HTTP/1.1" 200 80
[2019-11-18 09:21:41,588] [basehttp.py:124] [basehttp:log_message] [INFO]- "POST /v1/users/user HTTP/1.1" 200 80
[2019-11-18 09:21:53,377] [basehttp.py:124] [basehttp:log_message] [INFO]- "POST /v1/users/user HTTP/1.1" 200 13
[2019-11-18 09:22:00,028] [basehttp.py:124] [basehttp:log_message] [INFO]- "POST /v1/users/user HTTP/1.1" 200 13
[2019-11-18 09:22:04,438] [basehttp.py:124] [basehttp:log_message] [INFO]- "POST /v1/users/user HTTP/1.1" 200 13
[2019-11-18 09:22:08,357] [basehttp.py:124] [basehttp:log_message] [INFO]- "POST /v1/users/user HTTP/1.1" 200 13
[2019-11-18 09:22:12,083] [basehttp.py:124] [basehttp:log_message] [INFO]- "POST /v1/users/user HTTP/1.1" 200 13
[2019-11-18 09:22:17,809] [basehttp.py:124] [basehttp:log_message] [INFO]- "POST /v1/users/user HTTP/1.1" 200 13
[2019-11-18 09:22:21,337] [basehttp.py:124] [basehttp:log_message] [INFO]- "POST /v1/users/user HTTP/1.1" 200 13
[2019-11-18 09:22:29,014] [basehttp.py:124] [basehttp:log_message] [INFO]- "POST /v1/users/user HTTP/1.1" 200 13
[2019-11-18 09:22:33,949] [basehttp.py:124] [basehttp:log_message] [INFO]- "POST /v1/users/user HTTP/1.1" 200 13
[2019-11-18 09:22:38,164] [basehttp.py:124] [basehttp:log_message] [INFO]- "GET /v1/users/user?page=1 HTTP/1.1" 200 1200
[2019-11-18 09:23:17,130] [exception.py:135] [exception:handle_uncaught_exception] [ERROR]- Internal Server Error: /v1/users/user
Traceback (most recent call last):
  File "/home/tarena/.local/lib/python3.6/site-packages/django/core/handlers/exception.py", line 41, in inner
    response = get_response(request)
  File "/home/tarena/.local/lib/python3.6/site-packages/django/core/handlers/base.py", line 187, in _get_response
    response = self.process_exception_by_middleware(e, request)
  File "/home/tarena/.local/lib/python3.6/site-packages/django/core/handlers/base.py", line 185, in _get_response
    response = wrapped_callback(request, *callback_args, **callback_kwargs)
  File "/home/tarena/.local/lib/python3.6/site-packages/django/views/generic/base.py", line 68, in view
    return self.dispatch(request, *args, **kwargs)
  File "/home/tarena/.local/lib/python3.6/site-packages/django/views/generic/base.py", line 88, in dispatch
    return handler(request, *args, **kwargs)
  File "/home/tarena/桌面/git/Storage/storage/users/views.py", line 28, in get
    print(data.number)
AttributeError: 'Paginator' object has no attribute 'number'
[2019-11-18 09:23:17,181] [basehttp.py:124] [basehttp:log_message] [ERROR]- "GET /v1/users/user?page=1 HTTP/1.1" 500 84934
[2019-11-18 09:24:03,757] [basehttp.py:124] [basehttp:log_message] [INFO]- "GET /v1/users/user?page=1 HTTP/1.1" 200 1200
[2019-11-18 09:25:05,681] [basehttp.py:124] [basehttp:log_message] [INFO]- "POST /v1/users/user HTTP/1.1" 200 13
[2019-11-18 09:25:09,147] [exception.py:135] [exception:handle_uncaught_exception] [ERROR]- Internal Server Error: /v1/users/user
Traceback (most recent call last):
  File "/home/tarena/.local/lib/python3.6/site-packages/django/core/handlers/exception.py", line 41, in inner
    response = get_response(request)
  File "/home/tarena/.local/lib/python3.6/site-packages/django/core/handlers/base.py", line 187, in _get_response
    response = self.process_exception_by_middleware(e, request)
  File "/home/tarena/.local/lib/python3.6/site-packages/django/core/handlers/base.py", line 185, in _get_response
    response = wrapped_callback(request, *callback_args, **callback_kwargs)
  File "/home/tarena/.local/lib/python3.6/site-packages/django/views/generic/base.py", line 68, in view
    return self.dispatch(request, *args, **kwargs)
  File "/home/tarena/.local/lib/python3.6/site-packages/django/views/generic/base.py", line 88, in dispatch
    return handler(request, *args, **kwargs)
  File "/home/tarena/桌面/git/Storage/storage/users/views.py", line 38, in post
    body = json.loads(request.body)
  File "/usr/lib/python3.6/json/__init__.py", line 354, in loads
    return _default_decoder.decode(s)
  File "/usr/lib/python3.6/json/decoder.py", line 339, in decode
    obj, end = self.raw_decode(s, idx=_w(s, 0).end())
  File "/usr/lib/python3.6/json/decoder.py", line 355, in raw_decode
    obj, end = self.scan_once(s, idx)
json.decoder.JSONDecodeError: Expecting ',' delimiter: line 3 column 2 (char 23)
[2019-11-18 09:25:09,198] [basehttp.py:124] [basehttp:log_message] [ERROR]- "POST /v1/users/user HTTP/1.1" 500 93313
[2019-11-18 09:25:16,602] [basehttp.py:124] [basehttp:log_message] [INFO]- "POST /v1/users/user HTTP/1.1" 200 13
[2019-11-18 09:25:18,777] [basehttp.py:124] [basehttp:log_message] [INFO]- "POST /v1/users/user HTTP/1.1" 200 13
[2019-11-18 09:25:20,838] [basehttp.py:124] [basehttp:log_message] [INFO]- "POST /v1/users/user HTTP/1.1" 200 13
[2019-11-18 09:25:22,647] [basehttp.py:124] [basehttp:log_message] [INFO]- "POST /v1/users/user HTTP/1.1" 200 13
[2019-11-18 09:25:24,374] [basehttp.py:124] [basehttp:log_message] [INFO]- "POST /v1/users/user HTTP/1.1" 200 13
[2019-11-18 09:25:25,998] [basehttp.py:124] [basehttp:log_message] [INFO]- "POST /v1/users/user HTTP/1.1" 200 13
[2019-11-18 09:25:27,555] [basehttp.py:124] [basehttp:log_message] [INFO]- "POST /v1/users/user HTTP/1.1" 200 13
[2019-11-18 09:25:33,389] [exception.py:135] [exception:handle_uncaught_exception] [ERROR]- Internal Server Error: /v1/users/user
Traceback (most recent call last):
  File "/home/tarena/.local/lib/python3.6/site-packages/django/core/handlers/exception.py", line 41, in inner
    response = get_response(request)
  File "/home/tarena/.local/lib/python3.6/site-packages/django/core/handlers/base.py", line 187, in _get_response
    response = self.process_exception_by_middleware(e, request)
  File "/home/tarena/.local/lib/python3.6/site-packages/django/core/handlers/base.py", line 185, in _get_response
    response = wrapped_callback(request, *callback_args, **callback_kwargs)
  File "/home/tarena/.local/lib/python3.6/site-packages/django/views/generic/base.py", line 68, in view
    return self.dispatch(request, *args, **kwargs)
  File "/home/tarena/.local/lib/python3.6/site-packages/django/views/generic/base.py", line 88, in dispatch
    return handler(request, *args, **kwargs)
  File "/home/tarena/桌面/git/Storage/storage/users/views.py", line 38, in post
    body = json.loads(request.body)
  File "/usr/lib/python3.6/json/__init__.py", line 354, in loads
    return _default_decoder.decode(s)
  File "/usr/lib/python3.6/json/decoder.py", line 339, in decode
    obj, end = self.raw_decode(s, idx=_w(s, 0).end())
  File "/usr/lib/python3.6/json/decoder.py", line 355, in raw_decode
    obj, end = self.scan_once(s, idx)
json.decoder.JSONDecodeError: Invalid control character at: line 3 column 17 (char 30)
[2019-11-18 09:25:33,433] [basehttp.py:124] [basehttp:log_message] [ERROR]- "POST /v1/users/user HTTP/1.1" 500 93267
[2019-11-18 09:25:36,405] [exception.py:135] [exception:handle_uncaught_exception] [ERROR]- Internal Server Error: /v1/users/user
Traceback (most recent call last):
  File "/home/tarena/.local/lib/python3.6/site-packages/django/core/handlers/exception.py", line 41, in inner
    response = get_response(request)
  File "/home/tarena/.local/lib/python3.6/site-packages/django/core/handlers/base.py", line 187, in _get_response
    response = self.process_exception_by_middleware(e, request)
  File "/home/tarena/.local/lib/python3.6/site-packages/django/core/handlers/base.py", line 185, in _get_response
    response = wrapped_callback(request, *callback_args, **callback_kwargs)
  File "/home/tarena/.local/lib/python3.6/site-packages/django/views/generic/base.py", line 68, in view
    return self.dispatch(request, *args, **kwargs)
  File "/home/tarena/.local/lib/python3.6/site-packages/django/views/generic/base.py", line 88, in dispatch
    return handler(request, *args, **kwargs)
  File "/home/tarena/桌面/git/Storage/storage/users/views.py", line 38, in post
    body = json.loads(request.body)
  File "/usr/lib/python3.6/json/__init__.py", line 354, in loads
    return _default_decoder.decode(s)
  File "/usr/lib/python3.6/json/decoder.py", line 339, in decode
    obj, end = self.raw_decode(s, idx=_w(s, 0).end())
  File "/usr/lib/python3.6/json/decoder.py", line 355, in raw_decode
    obj, end = self.scan_once(s, idx)
json.decoder.JSONDecodeError: Invalid control character at: line 3 column 17 (char 29)
[2019-11-18 09:25:36,439] [basehttp.py:124] [basehttp:log_message] [ERROR]- "POST /v1/users/user HTTP/1.1" 500 93264
[2019-11-18 09:25:41,543] [exception.py:135] [exception:handle_uncaught_exception] [ERROR]- Internal Server Error: /v1/users/user
Traceback (most recent call last):
  File "/home/tarena/.local/lib/python3.6/site-packages/django/core/handlers/exception.py", line 41, in inner
    response = get_response(request)
  File "/home/tarena/.local/lib/python3.6/site-packages/django/core/handlers/base.py", line 187, in _get_response
    response = self.process_exception_by_middleware(e, request)
  File "/home/tarena/.local/lib/python3.6/site-packages/django/core/handlers/base.py", line 185, in _get_response
    response = wrapped_callback(request, *callback_args, **callback_kwargs)
  File "/home/tarena/.local/lib/python3.6/site-packages/django/views/generic/base.py", line 68, in view
    return self.dispatch(request, *args, **kwargs)
  File "/home/tarena/.local/lib/python3.6/site-packages/django/views/generic/base.py", line 88, in dispatch
    return handler(request, *args, **kwargs)
  File "/home/tarena/桌面/git/Storage/storage/users/views.py", line 38, in post
    body = json.loads(request.body)
  File "/usr/lib/python3.6/json/__init__.py", line 354, in loads
    return _default_decoder.decode(s)
  File "/usr/lib/python3.6/json/decoder.py", line 339, in decode
    obj, end = self.raw_decode(s, idx=_w(s, 0).end())
  File "/usr/lib/python3.6/json/decoder.py", line 355, in raw_decode
    obj, end = self.scan_once(s, idx)
json.decoder.JSONDecodeError: Invalid control character at: line 3 column 17 (char 30)
[2019-11-18 09:25:41,596] [basehttp.py:124] [basehttp:log_message] [ERROR]- "POST /v1/users/user HTTP/1.1" 500 93267
[2019-11-18 09:25:49,516] [basehttp.py:124] [basehttp:log_message] [INFO]- "GET /v1/users/user?page=1 HTTP/1.1" 200 2000
[2019-11-18 09:26:44,230] [basehttp.py:124] [basehttp:log_message] [INFO]- "GET /v1/users/user?page=1 HTTP/1.1" 200 2000
[2019-11-18 09:26:56,286] [basehttp.py:124] [basehttp:log_message] [INFO]- "GET /v1/users/user?page=1 HTTP/1.1" 200 2000
[2019-11-18 09:27:42,618] [basehttp.py:124] [basehttp:log_message] [INFO]- "GET /v1/users/user?page=1 HTTP/1.1" 200 2000
[2019-11-18 09:27:51,136] [basehttp.py:124] [basehttp:log_message] [INFO]- "GET /v1/users/user?page=1 HTTP/1.1" 200 2000
[2019-11-18 09:30:26,824] [exception.py:135] [exception:handle_uncaught_exception] [ERROR]- Internal Server Error: /v1/users/user
Traceback (most recent call last):
  File "/home/tarena/.local/lib/python3.6/site-packages/django/core/handlers/exception.py", line 41, in inner
    response = get_response(request)
  File "/home/tarena/.local/lib/python3.6/site-packages/django/core/handlers/base.py", line 187, in _get_response
    response = self.process_exception_by_middleware(e, request)
  File "/home/tarena/.local/lib/python3.6/site-packages/django/core/handlers/base.py", line 185, in _get_response
    response = wrapped_callback(request, *callback_args, **callback_kwargs)
  File "/home/tarena/.local/lib/python3.6/site-packages/django/views/generic/base.py", line 68, in view
    return self.dispatch(request, *args, **kwargs)
  File "/home/tarena/.local/lib/python3.6/site-packages/django/views/generic/base.py", line 88, in dispatch
    return handler(request, *args, **kwargs)
  File "/home/tarena/桌面/git/Storage/storage/users/views.py", line 32, in get
    print(data.num_pages)
AttributeError: 'Page' object has no attribute 'num_pages'
[2019-11-18 09:30:26,873] [basehttp.py:124] [basehttp:log_message] [ERROR]- "GET /v1/users/user?page=1 HTTP/1.1" 500 82284
[2019-11-18 09:30:43,701] [basehttp.py:124] [basehttp:log_message] [INFO]- "GET /v1/users/user?page=1 HTTP/1.1" 200 226
[2019-11-18 09:33:09,452] [exception.py:135] [exception:handle_uncaught_exception] [ERROR]- Internal Server Error: /v1/users/user
Traceback (most recent call last):
  File "/home/tarena/.local/lib/python3.6/site-packages/django/core/handlers/exception.py", line 41, in inner
    response = get_response(request)
  File "/home/tarena/.local/lib/python3.6/site-packages/django/core/handlers/base.py", line 187, in _get_response
    response = self.process_exception_by_middleware(e, request)
  File "/home/tarena/.local/lib/python3.6/site-packages/django/core/handlers/base.py", line 185, in _get_response
    response = wrapped_callback(request, *callback_args, **callback_kwargs)
  File "/home/tarena/.local/lib/python3.6/site-packages/django/views/generic/base.py", line 68, in view
    return self.dispatch(request, *args, **kwargs)
  File "/home/tarena/.local/lib/python3.6/site-packages/django/views/generic/base.py", line 88, in dispatch
    return handler(request, *args, **kwargs)
  File "/home/tarena/桌面/git/Storage/storage/users/views.py", line 31, in get
    print('总页数是：', res['data'].num_pages)
AttributeError: 'dict' object has no attribute 'num_pages'
[2019-11-18 09:33:09,500] [basehttp.py:124] [basehttp:log_message] [ERROR]- "GET /v1/users/user?page=1 HTTP/1.1" 500 82421
[2019-11-18 09:35:23,904] [exception.py:135] [exception:handle_uncaught_exception] [ERROR]- Internal Server Error: /v1/users/user
Traceback (most recent call last):
  File "/home/tarena/.local/lib/python3.6/site-packages/django/core/handlers/exception.py", line 41, in inner
    response = get_response(request)
  File "/home/tarena/.local/lib/python3.6/site-packages/django/core/handlers/base.py", line 187, in _get_response
    response = self.process_exception_by_middleware(e, request)
  File "/home/tarena/.local/lib/python3.6/site-packages/django/core/handlers/base.py", line 185, in _get_response
    response = wrapped_callback(request, *callback_args, **callback_kwargs)
  File "/home/tarena/.local/lib/python3.6/site-packages/django/views/generic/base.py", line 68, in view
    return self.dispatch(request, *args, **kwargs)
  File "/home/tarena/.local/lib/python3.6/site-packages/django/views/generic/base.py", line 88, in dispatch
    return handler(request, *args, **kwargs)
  File "/home/tarena/桌面/git/Storage/storage/users/views.py", line 32, in get
    print('当前对象的面码范围是:', paginator.page_range)
AttributeError: 'Page' object has no attribute 'page_range'
[2019-11-18 09:35:23,953] [basehttp.py:124] [basehttp:log_message] [ERROR]- "GET /v1/users/user?page=1 HTTP/1.1" 500 81999
[2019-11-18 09:36:00,997] [exception.py:135] [exception:handle_uncaught_exception] [ERROR]- Internal Server Error: /v1/users/user
Traceback (most recent call last):
  File "/home/tarena/.local/lib/python3.6/site-packages/django/core/handlers/exception.py", line 41, in inner
    response = get_response(request)
  File "/home/tarena/.local/lib/python3.6/site-packages/django/core/handlers/base.py", line 187, in _get_response
    response = self.process_exception_by_middleware(e, request)
  File "/home/tarena/.local/lib/python3.6/site-packages/django/core/handlers/base.py", line 185, in _get_response
    response = wrapped_callback(request, *callback_args, **callback_kwargs)
  File "/home/tarena/.local/lib/python3.6/site-packages/django/views/generic/base.py", line 68, in view
    return self.dispatch(request, *args, **kwargs)
  File "/home/tarena/.local/lib/python3.6/site-packages/django/views/generic/base.py", line 88, in dispatch
    return handler(request, *args, **kwargs)
  File "/home/tarena/桌面/git/Storage/storage/users/views.py", line 34, in get
    print('总页数是：', paginator.num_pages)
AttributeError: 'Page' object has no attribute 'num_pages'
[2019-11-18 09:36:01,065] [basehttp.py:124] [basehttp:log_message] [ERROR]- "GET /v1/users/user?page=1 HTTP/1.1" 500 82064
[2019-11-18 09:36:24,028] [exception.py:135] [exception:handle_uncaught_exception] [ERROR]- Internal Server Error: /v1/users/user
Traceback (most recent call last):
  File "/home/tarena/.local/lib/python3.6/site-packages/django/core/handlers/exception.py", line 41, in inner
    response = get_response(request)
  File "/home/tarena/.local/lib/python3.6/site-packages/django/core/handlers/base.py", line 187, in _get_response
    response = self.process_exception_by_middleware(e, request)
  File "/home/tarena/.local/lib/python3.6/site-packages/django/core/handlers/base.py", line 185, in _get_response
    response = wrapped_callback(request, *callback_args, **callback_kwargs)
  File "/home/tarena/.local/lib/python3.6/site-packages/django/views/generic/base.py", line 68, in view
    return self.dispatch(request, *args, **kwargs)
  File "/home/tarena/.local/lib/python3.6/site-packages/django/views/generic/base.py", line 88, in dispatch
    return handler(request, *args, **kwargs)
  File "/home/tarena/桌面/git/Storage/storage/users/views.py", line 36, in get
    res = {'data': LinqHelper.res_format(code, data.paginator.page(page))}
AttributeError: 'Paginator' object has no attribute 'paginator'
[2019-11-18 09:36:24,082] [basehttp.py:124] [basehttp:log_message] [ERROR]- "GET /v1/users/user?page=1 HTTP/1.1" 500 82128
[2019-11-18 09:36:53,749] [exception.py:135] [exception:handle_uncaught_exception] [ERROR]- Internal Server Error: /v1/users/user
Traceback (most recent call last):
  File "/home/tarena/.local/lib/python3.6/site-packages/django/core/handlers/exception.py", line 41, in inner
    response = get_response(request)
  File "/home/tarena/.local/lib/python3.6/site-packages/django/core/handlers/base.py", line 187, in _get_response
    response = self.process_exception_by_middleware(e, request)
  File "/home/tarena/.local/lib/python3.6/site-packages/django/core/handlers/base.py", line 185, in _get_response
    response = wrapped_callback(request, *callback_args, **callback_kwargs)
  File "/home/tarena/.local/lib/python3.6/site-packages/django/views/generic/base.py", line 68, in view
    return self.dispatch(request, *args, **kwargs)
  File "/home/tarena/.local/lib/python3.6/site-packages/django/views/generic/base.py", line 88, in dispatch
    return handler(request, *args, **kwargs)
  File "/home/tarena/桌面/git/Storage/storage/users/views.py", line 36, in get
    res = {'data': LinqHelper.res_format(code, paginator.page(page))}
AttributeError: 'Page' object has no attribute 'page'
[2019-11-18 09:36:53,804] [basehttp.py:124] [basehttp:log_message] [ERROR]- "GET /v1/users/user?page=1 HTTP/1.1" 500 82078
[2019-11-18 09:37:52,308] [exception.py:135] [exception:handle_uncaught_exception] [ERROR]- Internal Server Error: /v1/users/user
Traceback (most recent call last):
  File "/home/tarena/.local/lib/python3.6/site-packages/django/core/handlers/exception.py", line 41, in inner
    response = get_response(request)
  File "/home/tarena/.local/lib/python3.6/site-packages/django/core/handlers/base.py", line 187, in _get_response
    response = self.process_exception_by_middleware(e, request)
  File "/home/tarena/.local/lib/python3.6/site-packages/django/core/handlers/base.py", line 185, in _get_response
    response = wrapped_callback(request, *callback_args, **callback_kwargs)
  File "/home/tarena/.local/lib/python3.6/site-packages/django/views/generic/base.py", line 68, in view
    return self.dispatch(request, *args, **kwargs)
  File "/home/tarena/.local/lib/python3.6/site-packages/django/views/generic/base.py", line 88, in dispatch
    return handler(request, *args, **kwargs)
  File "/home/tarena/桌面/git/Storage/storage/users/views.py", line 35, in get
    print(res)
  File "/home/tarena/桌面/git/Storage/storage/common/LinqHelper.py", line 26, in res_format
    for model_itme in list(list_msg.values()):
AttributeError: 'Page' object has no attribute 'values'
[2019-11-18 09:37:52,359] [basehttp.py:124] [basehttp:log_message] [ERROR]- "GET /v1/users/user?page=1 HTTP/1.1" 500 86322
[2019-11-18 09:38:29,451] [basehttp.py:124] [basehttp:log_message] [INFO]- "GET /v1/users/user?page=1 HTTP/1.1" 200 12
[2019-11-18 09:39:11,848] [basehttp.py:124] [basehttp:log_message] [INFO]- "GET /v1/users/user?page=1 HTTP/1.1" 200 12
[2019-11-18 09:39:18,136] [basehttp.py:124] [basehttp:log_message] [INFO]- "GET /v1/users/user?page=1 HTTP/1.1" 200 12
[2019-11-18 09:39:29,753] [basehttp.py:124] [basehttp:log_message] [INFO]- "GET /v1/users/user?page=1 HTTP/1.1" 200 12
[2019-11-18 09:39:56,293] [basehttp.py:124] [basehttp:log_message] [INFO]- "GET /v1/users/user?page=1 HTTP/1.1" 200 12
[2019-11-18 09:41:11,580] [exception.py:135] [exception:handle_uncaught_exception] [ERROR]- Internal Server Error: /v1/users/user
Traceback (most recent call last):
  File "/home/tarena/.local/lib/python3.6/site-packages/django/core/handlers/exception.py", line 41, in inner
    response = get_response(request)
  File "/home/tarena/.local/lib/python3.6/site-packages/django/core/handlers/base.py", line 187, in _get_response
    response = self.process_exception_by_middleware(e, request)
  File "/home/tarena/.local/lib/python3.6/site-packages/django/core/handlers/base.py", line 185, in _get_response
    response = wrapped_callback(request, *callback_args, **callback_kwargs)
  File "/home/tarena/.local/lib/python3.6/site-packages/django/views/generic/base.py", line 68, in view
    return self.dispatch(request, *args, **kwargs)
  File "/home/tarena/.local/lib/python3.6/site-packages/django/views/generic/base.py", line 88, in dispatch
    return handler(request, *args, **kwargs)
  File "/home/tarena/桌面/git/Storage/storage/users/views.py", line 50, in post
    body = json.loads(request.body)
  File "/usr/lib/python3.6/json/__init__.py", line 354, in loads
    return _default_decoder.decode(s)
  File "/usr/lib/python3.6/json/decoder.py", line 339, in decode
    obj, end = self.raw_decode(s, idx=_w(s, 0).end())
  File "/usr/lib/python3.6/json/decoder.py", line 355, in raw_decode
    obj, end = self.scan_once(s, idx)
json.decoder.JSONDecodeError: Invalid control character at: line 3 column 17 (char 30)
[2019-11-18 09:41:11,633] [basehttp.py:124] [basehttp:log_message] [ERROR]- "POST /v1/users/user HTTP/1.1" 500 93267
[2019-11-18 09:41:41,992] [exception.py:135] [exception:handle_uncaught_exception] [ERROR]- Internal Server Error: /v1/users/user
Traceback (most recent call last):
  File "/home/tarena/.local/lib/python3.6/site-packages/django/core/handlers/exception.py", line 41, in inner
    response = get_response(request)
  File "/home/tarena/.local/lib/python3.6/site-packages/django/core/handlers/base.py", line 187, in _get_response
    response = self.process_exception_by_middleware(e, request)
  File "/home/tarena/.local/lib/python3.6/site-packages/django/core/handlers/base.py", line 185, in _get_response
    response = wrapped_callback(request, *callback_args, **callback_kwargs)
  File "/home/tarena/.local/lib/python3.6/site-packages/django/views/generic/base.py", line 68, in view
    return self.dispatch(request, *args, **kwargs)
  File "/home/tarena/.local/lib/python3.6/site-packages/django/views/generic/base.py", line 88, in dispatch
    return handler(request, *args, **kwargs)
  File "/home/tarena/桌面/git/Storage/storage/users/views.py", line 50, in post
    body = json.loads(request.body)
  File "/usr/lib/python3.6/json/__init__.py", line 354, in loads
    return _default_decoder.decode(s)
  File "/usr/lib/python3.6/json/decoder.py", line 339, in decode
    obj, end = self.raw_decode(s, idx=_w(s, 0).end())
  File "/usr/lib/python3.6/json/decoder.py", line 355, in raw_decode
    obj, end = self.scan_once(s, idx)
json.decoder.JSONDecodeError: Invalid control character at: line 3 column 17 (char 30)
[2019-11-18 09:41:42,052] [basehttp.py:124] [basehttp:log_message] [ERROR]- "POST /v1/users/user HTTP/1.1" 500 93267
[2019-11-18 09:41:57,005] [basehttp.py:124] [basehttp:log_message] [INFO]- "GET /v1/users/user?page=1 HTTP/1.1" 200 12
[2019-11-18 09:42:47,785] [exception.py:135] [exception:handle_uncaught_exception] [ERROR]- Internal Server Error: /v1/users/user
Traceback (most recent call last):
  File "/home/tarena/.local/lib/python3.6/site-packages/django/core/handlers/exception.py", line 41, in inner
    response = get_response(request)
  File "/home/tarena/.local/lib/python3.6/site-packages/django/core/handlers/base.py", line 187, in _get_response
    response = self.process_exception_by_middleware(e, request)
  File "/home/tarena/.local/lib/python3.6/site-packages/django/core/handlers/base.py", line 185, in _get_response
    response = wrapped_callback(request, *callback_args, **callback_kwargs)
  File "/home/tarena/.local/lib/python3.6/site-packages/django/views/generic/base.py", line 68, in view
    return self.dispatch(request, *args, **kwargs)
  File "/home/tarena/.local/lib/python3.6/site-packages/django/views/generic/base.py", line 88, in dispatch
    return handler(request, *args, **kwargs)
  File "/home/tarena/桌面/git/Storage/storage/users/views.py", line 39, in get
    print(page.per_page)
AttributeError: 'Page' object has no attribute 'per_page'
[2019-11-18 09:42:47,837] [basehttp.py:124] [basehttp:log_message] [ERROR]- "GET /v1/users/user?page=1 HTTP/1.1" 500 81784
[2019-11-18 09:44:38,194] [basehttp.py:124] [basehttp:log_message] [INFO]- "GET /v1/users/user?page=1 HTTP/1.1" 200 12
[2019-11-18 09:45:28,277] [basehttp.py:124] [basehttp:log_message] [INFO]- "GET /v1/users/user?page=1 HTTP/1.1" 200 12
[2019-11-18 09:45:50,814] [basehttp.py:124] [basehttp:log_message] [INFO]- "GET /v1/users/user?page=1 HTTP/1.1" 200 12
[2019-11-18 09:46:04,157] [basehttp.py:124] [basehttp:log_message] [INFO]- "GET /v1/users/user?page=1 HTTP/1.1" 200 12
[2019-11-18 09:46:33,454] [basehttp.py:124] [basehttp:log_message] [INFO]- "GET /v1/users/user?page=1 HTTP/1.1" 200 12
[2019-11-18 09:55:57,681] [basehttp.py:124] [basehttp:log_message] [INFO]- "GET /v1/users/user?page=1 HTTP/1.1" 200 470
[2019-11-18 09:56:25,281] [basehttp.py:124] [basehttp:log_message] [INFO]- "GET /v1/users/user?page=1 HTTP/1.1" 200 255
[2019-11-18 09:56:55,217] [exception.py:135] [exception:handle_uncaught_exception] [ERROR]- Internal Server Error: /v1/users/user
Traceback (most recent call last):
  File "/home/tarena/.local/lib/python3.6/site-packages/django/core/handlers/exception.py", line 41, in inner
    response = get_response(request)
  File "/home/tarena/.local/lib/python3.6/site-packages/django/core/handlers/base.py", line 187, in _get_response
    response = self.process_exception_by_middleware(e, request)
  File "/home/tarena/.local/lib/python3.6/site-packages/django/core/handlers/base.py", line 185, in _get_response
    response = wrapped_callback(request, *callback_args, **callback_kwargs)
  File "/home/tarena/.local/lib/python3.6/site-packages/django/views/generic/base.py", line 68, in view
    return self.dispatch(request, *args, **kwargs)
  File "/home/tarena/.local/lib/python3.6/site-packages/django/views/generic/base.py", line 88, in dispatch
    return handler(request, *args, **kwargs)
  File "/home/tarena/桌面/git/Storage/storage/users/views.py", line 41, in get
    return JsonResponse(res)
  File "/home/tarena/.local/lib/python3.6/site-packages/django/http/response.py", line 530, in __init__
    data = json.dumps(data, cls=encoder, **json_dumps_params)
  File "/usr/lib/python3.6/json/__init__.py", line 238, in dumps
    **kw).encode(obj)
  File "/usr/lib/python3.6/json/encoder.py", line 199, in encode
    chunks = self.iterencode(o, _one_shot=True)
  File "/usr/lib/python3.6/json/encoder.py", line 257, in iterencode
    return _iterencode(o, 0)
  File "/home/tarena/.local/lib/python3.6/site-packages/django/core/serializers/json.py", line 124, in default
    return super(DjangoJSONEncoder, self).default(o)
  File "/usr/lib/python3.6/json/encoder.py", line 180, in default
    o.__class__.__name__)
TypeError: Object of type 'range' is not JSON serializable
[2019-11-18 09:56:55,277] [basehttp.py:124] [basehttp:log_message] [ERROR]- "GET /v1/users/user?page=1 HTTP/1.1" 500 111024
[2019-11-18 09:57:17,991] [basehttp.py:124] [basehttp:log_message] [INFO]- "GET /v1/users/user?page=1 HTTP/1.1" 200 284
[2019-11-18 09:57:53,912] [exception.py:135] [exception:handle_uncaught_exception] [ERROR]- Internal Server Error: /v1/users/user
Traceback (most recent call last):
  File "/home/tarena/.local/lib/python3.6/site-packages/django/core/handlers/exception.py", line 41, in inner
    response = get_response(request)
  File "/home/tarena/.local/lib/python3.6/site-packages/django/core/handlers/base.py", line 187, in _get_response
    response = self.process_exception_by_middleware(e, request)
  File "/home/tarena/.local/lib/python3.6/site-packages/django/core/handlers/base.py", line 185, in _get_response
    response = wrapped_callback(request, *callback_args, **callback_kwargs)
  File "/home/tarena/.local/lib/python3.6/site-packages/django/views/generic/base.py", line 68, in view
    return self.dispatch(request, *args, **kwargs)
  File "/home/tarena/.local/lib/python3.6/site-packages/django/views/generic/base.py", line 88, in dispatch
    return handler(request, *args, **kwargs)
  File "/home/tarena/桌面/git/Storage/storage/users/views.py", line 33, in get
    res['pages'] = list(data.num_pages)
TypeError: 'int' object is not iterable
[2019-11-18 09:57:53,970] [basehttp.py:124] [basehttp:log_message] [ERROR]- "GET /v1/users/user?page=1 HTTP/1.1" 500 82369
[2019-11-18 09:58:02,910] [basehttp.py:124] [basehttp:log_message] [INFO]- "GET /v1/users/user?page=1 HTTP/1.1" 200 255
[2019-11-18 10:13:02,012] [exception.py:135] [exception:handle_uncaught_exception] [ERROR]- Internal Server Error: /v1/users/user
Traceback (most recent call last):
  File "/home/tarena/.local/lib/python3.6/site-packages/django/core/handlers/exception.py", line 41, in inner
    response = get_response(request)
  File "/home/tarena/.local/lib/python3.6/site-packages/django/core/handlers/base.py", line 187, in _get_response
    response = self.process_exception_by_middleware(e, request)
  File "/home/tarena/.local/lib/python3.6/site-packages/django/core/handlers/base.py", line 185, in _get_response
    response = wrapped_callback(request, *callback_args, **callback_kwargs)
  File "/home/tarena/.local/lib/python3.6/site-packages/django/views/generic/base.py", line 68, in view
    return self.dispatch(request, *args, **kwargs)
  File "/home/tarena/.local/lib/python3.6/site-packages/django/views/generic/base.py", line 88, in dispatch
    return handler(request, *args, **kwargs)
  File "/home/tarena/桌面/git/Storage/storage/users/views.py", line 34, in get
    print('上一页', pages.previous_page_number)
AttributeError: 'QuerySet' object has no attribute 'previous_page_number'
[2019-11-18 10:13:02,063] [basehttp.py:124] [basehttp:log_message] [ERROR]- "GET /v1/users/user?page=1 HTTP/1.1" 500 82754
[2019-11-18 10:13:42,139] [basehttp.py:124] [basehttp:log_message] [INFO]- "GET /v1/users/user?page=1 HTTP/1.1" 200 255
[2019-11-18 10:14:23,203] [basehttp.py:124] [basehttp:log_message] [INFO]- "GET /v1/users/user?page=1 HTTP/1.1" 200 255
[2019-11-18 10:14:33,938] [basehttp.py:124] [basehttp:log_message] [INFO]- "GET /v1/users/user?page=1 HTTP/1.1" 200 255
[2019-11-18 10:15:32,225] [basehttp.py:124] [basehttp:log_message] [INFO]- "GET /v1/users/user?page=1 HTTP/1.1" 200 255
[2019-11-18 10:15:44,094] [basehttp.py:124] [basehttp:log_message] [INFO]- "GET /v1/users/user?page=1 HTTP/1.1" 200 255
[2019-11-18 10:16:03,798] [basehttp.py:124] [basehttp:log_message] [INFO]- "GET /v1/users/user?page=1 HTTP/1.1" 200 255
[2019-11-18 10:23:17,890] [basehttp.py:124] [basehttp:log_message] [INFO]- "GET /v1/users/user?page=1 HTTP/1.1" 200 253
[2019-11-18 10:23:29,381] [exception.py:135] [exception:handle_uncaught_exception] [ERROR]- Internal Server Error: /v1/users/user
Traceback (most recent call last):
  File "/home/tarena/.local/lib/python3.6/site-packages/django/core/handlers/exception.py", line 41, in inner
    response = get_response(request)
  File "/home/tarena/.local/lib/python3.6/site-packages/django/core/handlers/base.py", line 187, in _get_response
    response = self.process_exception_by_middleware(e, request)
  File "/home/tarena/.local/lib/python3.6/site-packages/django/core/handlers/base.py", line 185, in _get_response
    response = wrapped_callback(request, *callback_args, **callback_kwargs)
  File "/home/tarena/.local/lib/python3.6/site-packages/django/views/generic/base.py", line 68, in view
    return self.dispatch(request, *args, **kwargs)
  File "/home/tarena/.local/lib/python3.6/site-packages/django/views/generic/base.py", line 88, in dispatch
    return handler(request, *args, **kwargs)
  File "/home/tarena/桌面/git/Storage/storage/users/views.py", line 26, in get
    page = int(page)
ValueError: invalid literal for int() with base 10: '1.4'
[2019-11-18 10:23:29,430] [basehttp.py:124] [basehttp:log_message] [ERROR]- "GET /v1/users/user?page=1.4 HTTP/1.1" 500 81460
[2019-11-18 10:24:03,919] [exception.py:135] [exception:handle_uncaught_exception] [ERROR]- Internal Server Error: /v1/users/user
Traceback (most recent call last):
  File "/home/tarena/.local/lib/python3.6/site-packages/django/core/handlers/exception.py", line 41, in inner
    response = get_response(request)
  File "/home/tarena/.local/lib/python3.6/site-packages/django/core/handlers/base.py", line 187, in _get_response
    response = self.process_exception_by_middleware(e, request)
  File "/home/tarena/.local/lib/python3.6/site-packages/django/core/handlers/base.py", line 185, in _get_response
    response = wrapped_callback(request, *callback_args, **callback_kwargs)
  File "/home/tarena/.local/lib/python3.6/site-packages/django/views/generic/base.py", line 68, in view
    return self.dispatch(request, *args, **kwargs)
  File "/home/tarena/.local/lib/python3.6/site-packages/django/views/generic/base.py", line 88, in dispatch
    return handler(request, *args, **kwargs)
  File "/home/tarena/桌面/git/Storage/storage/users/views.py", line 26, in get
    page = int(float(page))
NameError: name 'floatpage' is not defined
[2019-11-18 10:24:03,965] [basehttp.py:124] [basehttp:log_message] [ERROR]- "GET /v1/users/user?page=1.4 HTTP/1.1" 500 81412
[2019-11-18 10:24:42,849] [exception.py:135] [exception:handle_uncaught_exception] [ERROR]- Internal Server Error: /v1/users/user
Traceback (most recent call last):
  File "/home/tarena/.local/lib/python3.6/site-packages/django/core/handlers/exception.py", line 41, in inner
    response = get_response(request)
  File "/home/tarena/.local/lib/python3.6/site-packages/django/core/handlers/base.py", line 187, in _get_response
    response = self.process_exception_by_middleware(e, request)
  File "/home/tarena/.local/lib/python3.6/site-packages/django/core/handlers/base.py", line 185, in _get_response
    response = wrapped_callback(request, *callback_args, **callback_kwargs)
  File "/home/tarena/.local/lib/python3.6/site-packages/django/views/generic/base.py", line 68, in view
    return self.dispatch(request, *args, **kwargs)
  File "/home/tarena/.local/lib/python3.6/site-packages/django/views/generic/base.py", line 88, in dispatch
    return handler(request, *args, **kwargs)
  File "/home/tarena/桌面/git/Storage/storage/users/views.py", line 26, in get
    page = float(int(page))
ValueError: invalid literal for int() with base 10: '1.4'
[2019-11-18 10:24:42,906] [basehttp.py:124] [basehttp:log_message] [ERROR]- "GET /v1/users/user?page=1.4 HTTP/1.1" 500 81474
[2019-11-18 10:26:20,540] [basehttp.py:124] [basehttp:log_message] [INFO]- "GET /v1/users/user?page=1.4 HTTP/1.1" 200 50
[2019-11-18 10:26:28,980] [basehttp.py:124] [basehttp:log_message] [INFO]- "GET /v1/users/user?page=1.4 HTTP/1.1" 200 50
[2019-11-18 10:26:32,921] [basehttp.py:124] [basehttp:log_message] [INFO]- "GET /v1/users/user?page=1.6 HTTP/1.1" 200 50
[2019-11-18 10:26:40,717] [basehttp.py:124] [basehttp:log_message] [INFO]- "GET /v1/users/user?page=2.0 HTTP/1.1" 200 50
[2019-11-18 10:26:45,256] [basehttp.py:124] [basehttp:log_message] [INFO]- "GET /v1/users/user?page=2 HTTP/1.1" 200 50
[2019-11-18 10:26:46,124] [basehttp.py:124] [basehttp:log_message] [INFO]- "GET /v1/users/user?page=2 HTTP/1.1" 200 50
[2019-11-18 10:26:46,548] [basehttp.py:124] [basehttp:log_message] [INFO]- "GET /v1/users/user?page=2 HTTP/1.1" 200 50
[2019-11-18 10:27:05,491] [basehttp.py:124] [basehttp:log_message] [INFO]- "GET /v1/users/user?page=2 HTTP/1.1" 200 276
[2019-11-18 10:27:10,613] [basehttp.py:124] [basehttp:log_message] [INFO]- "GET /v1/users/user?page=2.0 HTTP/1.1" 200 276
[2019-11-18 10:27:14,019] [basehttp.py:124] [basehttp:log_message] [INFO]- "GET /v1/users/user?page=2.1 HTTP/1.1" 200 276
[2019-11-18 10:27:25,975] [exception.py:135] [exception:handle_uncaught_exception] [ERROR]- Internal Server Error: /v1/users/user
Traceback (most recent call last):
  File "/home/tarena/.local/lib/python3.6/site-packages/django/core/handlers/exception.py", line 41, in inner
    response = get_response(request)
  File "/home/tarena/.local/lib/python3.6/site-packages/django/core/handlers/base.py", line 187, in _get_response
    response = self.process_exception_by_middleware(e, request)
  File "/home/tarena/.local/lib/python3.6/site-packages/django/core/handlers/base.py", line 185, in _get_response
    response = wrapped_callback(request, *callback_args, **callback_kwargs)
  File "/home/tarena/.local/lib/python3.6/site-packages/django/views/generic/base.py", line 68, in view
    return self.dispatch(request, *args, **kwargs)
  File "/home/tarena/.local/lib/python3.6/site-packages/django/views/generic/base.py", line 88, in dispatch
    return handler(request, *args, **kwargs)
  File "/home/tarena/桌面/git/Storage/storage/users/views.py", line 26, in get
    page = int(float(page))
ValueError: could not convert string to float: '2.1q'
[2019-11-18 10:27:26,030] [basehttp.py:124] [basehttp:log_message] [ERROR]- "GET /v1/users/user?page=2.1q HTTP/1.1" 500 81469
[2019-11-18 10:28:49,380] [basehttp.py:124] [basehttp:log_message] [INFO]- "GET /v1/users/user?page=2.1q HTTP/1.1" 200 50
[2019-11-18 10:28:54,054] [basehttp.py:124] [basehttp:log_message] [INFO]- "GET /v1/users/user?page=2.1q HTTP/1.1" 200 50
[2019-11-18 10:28:57,419] [basehttp.py:124] [basehttp:log_message] [INFO]- "GET /v1/users/user?page=2.1 HTTP/1.1" 200 50
[2019-11-18 10:29:02,070] [basehttp.py:124] [basehttp:log_message] [INFO]- "GET /v1/users/user?page=2.0 HTTP/1.1" 200 50
[2019-11-18 10:29:14,496] [views.py:35] [views:get] [ERROR]- 添加失败：本页结果未空
[2019-11-18 10:29:14,496] [basehttp.py:124] [basehttp:log_message] [INFO]- "GET /v1/users/user?page=20 HTTP/1.1" 200 50
[2019-11-18 10:30:11,148] [basehttp.py:124] [basehttp:log_message] [INFO]- "GET /v1/users/user?page=20 HTTP/1.1" 200 50
[2019-11-18 10:30:33,244] [views.py:38] [views:get] [ERROR]- 添加失败：本页结果未空
[2019-11-18 10:30:33,245] [basehttp.py:124] [basehttp:log_message] [INFO]- "GET /v1/users/user?page=20 HTTP/1.1" 200 50
[2019-11-18 10:30:56,821] [views.py:38] [views:get] [ERROR]- 添加失败：本页结果未空
[2019-11-18 10:30:56,822] [basehttp.py:124] [basehttp:log_message] [INFO]- "GET /v1/users/user?page=20 HTTP/1.1" 200 50
[2019-11-18 10:31:36,882] [views.py:38] [views:get] [ERROR]- 添加失败：本页结果未空
[2019-11-18 10:31:36,883] [basehttp.py:124] [basehttp:log_message] [INFO]- "GET /v1/users/user?page=20 HTTP/1.1" 200 50
[2019-11-18 10:31:53,360] [views.py:38] [views:get] [ERROR]- 添加失败：本页结果未空
[2019-11-18 10:31:53,361] [basehttp.py:124] [basehttp:log_message] [INFO]- "GET /v1/users/user?page=20 HTTP/1.1" 200 50
[2019-11-18 10:32:08,554] [views.py:39] [views:get] [ERROR]- 添加失败：本页结果未空
[2019-11-18 10:32:08,554] [basehttp.py:124] [basehttp:log_message] [INFO]- "GET /v1/users/user?page=20 HTTP/1.1" 200 50
[2019-11-18 10:32:39,706] [views.py:39] [views:get] [ERROR]- 添加失败：本页结果未空
[2019-11-18 10:32:39,707] [basehttp.py:124] [basehttp:log_message] [INFO]- "GET /v1/users/user?page=20 HTTP/1.1" 200 50
[2019-11-18 10:32:46,953] [views.py:38] [views:get] [ERROR]- 添加失败：本页结果未空
[2019-11-18 10:32:46,954] [basehttp.py:124] [basehttp:log_message] [INFO]- "GET /v1/users/user?page=20 HTTP/1.1" 200 50
[2019-11-18 10:32:50,240] [basehttp.py:124] [basehttp:log_message] [INFO]- "GET /v1/users/user?page=2.0 HTTP/1.1" 200 50
[2019-11-18 10:33:00,101] [basehttp.py:124] [basehttp:log_message] [INFO]- "GET /v1/users/user?page=2.0 HTTP/1.1" 200 50
[2019-11-18 10:33:03,403] [basehttp.py:124] [basehttp:log_message] [INFO]- "GET /v1/users/user?page=2.0 HTTP/1.1" 200 50
[2019-11-18 10:33:25,232] [basehttp.py:124] [basehttp:log_message] [INFO]- "GET /v1/users/user?page=2.0 HTTP/1.1" 200 50
[2019-11-18 10:33:49,984] [basehttp.py:124] [basehttp:log_message] [INFO]- "GET /v1/users/user?page=2.0 HTTP/1.1" 200 50
[2019-11-18 10:34:01,769] [basehttp.py:124] [basehttp:log_message] [INFO]- "GET /v1/users/user?page=2.0 HTTP/1.1" 200 50
[2019-11-18 10:37:34,817] [views.py:31] [views:get] [ERROR]- 添加失败：页号不是整数
[2019-11-18 10:37:34,818] [basehttp.py:124] [basehttp:log_message] [INFO]- "GET /v1/users/user?page=2.0 HTTP/1.1" 200 50
[2019-11-18 10:37:35,664] [views.py:31] [views:get] [ERROR]- 添加失败：页号不是整数
[2019-11-18 10:37:35,665] [basehttp.py:124] [basehttp:log_message] [INFO]- "GET /v1/users/user?page=2.0 HTTP/1.1" 200 50
[2019-11-18 10:39:01,130] [exception.py:135] [exception:handle_uncaught_exception] [ERROR]- Internal Server Error: /v1/users/user
Traceback (most recent call last):
  File "/home/tarena/.local/lib/python3.6/site-packages/django/core/handlers/exception.py", line 41, in inner
    response = get_response(request)
  File "/home/tarena/.local/lib/python3.6/site-packages/django/core/handlers/base.py", line 187, in _get_response
    response = self.process_exception_by_middleware(e, request)
  File "/home/tarena/.local/lib/python3.6/site-packages/django/core/handlers/base.py", line 185, in _get_response
    response = wrapped_callback(request, *callback_args, **callback_kwargs)
  File "/home/tarena/.local/lib/python3.6/site-packages/django/views/generic/base.py", line 68, in view
    return self.dispatch(request, *args, **kwargs)
  File "/home/tarena/.local/lib/python3.6/site-packages/django/views/generic/base.py", line 88, in dispatch
    return handler(request, *args, **kwargs)
  File "/home/tarena/桌面/git/Storage/storage/users/views.py", line 25, in get
    if re.compile(r'^[-+]?[-0-9]\d*\.\d*|[-+]?\.?[0-9]\d*$').pattern.match(page):
AttributeError: 'str' object has no attribute 'match'
[2019-11-18 10:39:01,180] [basehttp.py:124] [basehttp:log_message] [ERROR]- "GET /v1/users/user?page=2.0 HTTP/1.1" 500 81486
[2019-11-18 10:43:40,517] [exception.py:135] [exception:handle_uncaught_exception] [ERROR]- Internal Server Error: /v1/users/user
Traceback (most recent call last):
  File "/home/tarena/.local/lib/python3.6/site-packages/django/core/handlers/exception.py", line 41, in inner
    response = get_response(request)
  File "/home/tarena/.local/lib/python3.6/site-packages/django/core/handlers/base.py", line 187, in _get_response
    response = self.process_exception_by_middleware(e, request)
  File "/home/tarena/.local/lib/python3.6/site-packages/django/core/handlers/base.py", line 185, in _get_response
    response = wrapped_callback(request, *callback_args, **callback_kwargs)
  File "/home/tarena/.local/lib/python3.6/site-packages/django/views/generic/base.py", line 68, in view
    return self.dispatch(request, *args, **kwargs)
  File "/home/tarena/.local/lib/python3.6/site-packages/django/views/generic/base.py", line 88, in dispatch
    return handler(request, *args, **kwargs)
  File "/home/tarena/桌面/git/Storage/storage/users/views.py", line 25, in get
    if re.compile(r'^[-+]?[-0-9]\d*\.\d*|[-+]?\.?[0-9]\d*$').pattern.match(page):
AttributeError: 'str' object has no attribute 'match'
[2019-11-18 10:43:40,551] [basehttp.py:124] [basehttp:log_message] [ERROR]- "GET /v1/users/user?page=2.0 HTTP/1.1" 500 81486
[2019-11-18 10:44:09,802] [basehttp.py:124] [basehttp:log_message] [INFO]- "GET /v1/users/user?page=2.0 HTTP/1.1" 200 276
[2019-11-18 10:44:14,582] [basehttp.py:124] [basehttp:log_message] [INFO]- "GET /v1/users/user?page=2.01 HTTP/1.1" 200 276
[2019-11-18 10:44:17,101] [exception.py:135] [exception:handle_uncaught_exception] [ERROR]- Internal Server Error: /v1/users/user
Traceback (most recent call last):
  File "/home/tarena/.local/lib/python3.6/site-packages/django/core/handlers/exception.py", line 41, in inner
    response = get_response(request)
  File "/home/tarena/.local/lib/python3.6/site-packages/django/core/handlers/base.py", line 187, in _get_response
    response = self.process_exception_by_middleware(e, request)
  File "/home/tarena/.local/lib/python3.6/site-packages/django/core/handlers/base.py", line 185, in _get_response
    response = wrapped_callback(request, *callback_args, **callback_kwargs)
  File "/home/tarena/.local/lib/python3.6/site-packages/django/views/generic/base.py", line 68, in view
    return self.dispatch(request, *args, **kwargs)
  File "/home/tarena/.local/lib/python3.6/site-packages/django/views/generic/base.py", line 88, in dispatch
    return handler(request, *args, **kwargs)
  File "/home/tarena/桌面/git/Storage/storage/users/views.py", line 26, in get
    page = int(float(page))
ValueError: could not convert string to float: '2.01a'
[2019-11-18 10:44:17,147] [basehttp.py:124] [basehttp:log_message] [ERROR]- "GET /v1/users/user?page=2.01a HTTP/1.1" 500 81459
[2019-11-18 10:45:29,038] [basehttp.py:124] [basehttp:log_message] [INFO]- "GET /v1/users/user?page=2.01a HTTP/1.1" 200 50
[2019-11-18 10:45:37,030] [basehttp.py:124] [basehttp:log_message] [INFO]- "GET /v1/users/user?page=2 HTTP/1.1" 200 50
[2019-11-18 10:45:38,359] [basehttp.py:124] [basehttp:log_message] [INFO]- "GET /v1/users/user?page=2 HTTP/1.1" 200 50
[2019-11-18 10:45:38,738] [basehttp.py:124] [basehttp:log_message] [INFO]- "GET /v1/users/user?page=2 HTTP/1.1" 200 50
[2019-11-18 10:45:39,351] [basehttp.py:124] [basehttp:log_message] [INFO]- "GET /v1/users/user?page=2 HTTP/1.1" 200 50
[2019-11-18 10:45:55,084] [basehttp.py:124] [basehttp:log_message] [INFO]- "GET /v1/users/user?page=2 HTTP/1.1" 200 50
[2019-11-18 10:46:15,204] [basehttp.py:124] [basehttp:log_message] [INFO]- "GET /v1/users/user?page=2 HTTP/1.1" 200 276
[2019-11-18 10:46:18,810] [views.py:37] [views:get] [ERROR]- 添加失败：本页结果未空
[2019-11-18 10:46:18,811] [basehttp.py:124] [basehttp:log_message] [INFO]- "GET /v1/users/user?page=21 HTTP/1.1" 200 50
[2019-11-18 10:46:30,205] [views.py:37] [views:get] [ERROR]- 添加失败：本页结果未空
[2019-11-18 10:46:30,205] [basehttp.py:124] [basehttp:log_message] [INFO]- "GET /v1/users/user?page=21 HTTP/1.1" 200 50
[2019-11-18 10:46:38,864] [views.py:37] [views:get] [ERROR]- 添加失败：本页结果未空
[2019-11-18 10:46:38,865] [basehttp.py:124] [basehttp:log_message] [INFO]- "GET /v1/users/user?page=21 HTTP/1.1" 200 51
[2019-11-18 10:48:20,375] [views.py:35] [views:get] [ERROR]- 添加失败：本页结果未空
[2019-11-18 10:48:20,375] [basehttp.py:124] [basehttp:log_message] [INFO]- "GET /v1/users/user?page=21 HTTP/1.1" 200 51
[2019-11-18 10:48:24,446] [basehttp.py:124] [basehttp:log_message] [INFO]- "GET /v1/users/user?page=2 HTTP/1.1" 200 276
[2019-11-18 10:48:42,207] [basehttp.py:124] [basehttp:log_message] [INFO]- "GET /v1/users/user?page=2 HTTP/1.1" 200 968
[2019-11-18 10:49:20,254] [basehttp.py:124] [basehttp:log_message] [INFO]- "GET /v1/users/user?id=1 HTTP/1.1" 200 106
[2019-11-18 10:49:23,886] [basehttp.py:124] [basehttp:log_message] [INFO]- "GET /v1/users/user?page=2 HTTP/1.1" 200 968
[2019-11-18 10:50:21,685] [basehttp.py:124] [basehttp:log_message] [INFO]- "GET /v1/users/user?page=2 HTTP/1.1" 200 968
[2019-11-18 10:50:47,031] [basehttp.py:124] [basehttp:log_message] [INFO]- "GET /v1/users/user?page=2 HTTP/1.1" 200 958
[2019-11-18 10:51:21,846] [exception.py:135] [exception:handle_uncaught_exception] [ERROR]- Internal Server Error: /v1/users/user
Traceback (most recent call last):
  File "/home/tarena/.local/lib/python3.6/site-packages/django/core/handlers/exception.py", line 41, in inner
    response = get_response(request)
  File "/home/tarena/.local/lib/python3.6/site-packages/django/core/handlers/base.py", line 187, in _get_response
    response = self.process_exception_by_middleware(e, request)
  File "/home/tarena/.local/lib/python3.6/site-packages/django/core/handlers/base.py", line 185, in _get_response
    response = wrapped_callback(request, *callback_args, **callback_kwargs)
  File "/home/tarena/.local/lib/python3.6/site-packages/django/views/generic/base.py", line 68, in view
    return self.dispatch(request, *args, **kwargs)
  File "/home/tarena/.local/lib/python3.6/site-packages/django/views/generic/base.py", line 88, in dispatch
    return handler(request, *args, **kwargs)
  File "/home/tarena/桌面/git/Storage/storage/users/views.py", line 35, in get
    res['pages'] = data.num_pages
TypeError: list indices must be integers or slices, not str
[2019-11-18 10:51:21,902] [basehttp.py:124] [basehttp:log_message] [ERROR]- "GET /v1/users/user?page=2 HTTP/1.1" 500 83605
[2019-11-18 10:51:51,924] [basehttp.py:124] [basehttp:log_message] [INFO]- "GET /v1/users/user?page=2 HTTP/1.1" 200 945
[2019-11-18 10:52:07,114] [basehttp.py:124] [basehttp:log_message] [INFO]- "GET /v1/users/user?page=2 HTTP/1.1" 200 958
[2019-11-18 10:52:47,459] [exception.py:135] [exception:handle_uncaught_exception] [ERROR]- Internal Server Error: /v1/users/user
Traceback (most recent call last):
  File "/home/tarena/.local/lib/python3.6/site-packages/django/core/handlers/exception.py", line 41, in inner
    response = get_response(request)
  File "/home/tarena/.local/lib/python3.6/site-packages/django/core/handlers/base.py", line 187, in _get_response
    response = self.process_exception_by_middleware(e, request)
  File "/home/tarena/.local/lib/python3.6/site-packages/django/core/handlers/base.py", line 185, in _get_response
    response = wrapped_callback(request, *callback_args, **callback_kwargs)
  File "/home/tarena/.local/lib/python3.6/site-packages/django/views/generic/base.py", line 68, in view
    return self.dispatch(request, *args, **kwargs)
  File "/home/tarena/.local/lib/python3.6/site-packages/django/views/generic/base.py", line 88, in dispatch
    return handler(request, *args, **kwargs)
  File "/home/tarena/桌面/git/Storage/storage/users/views.py", line 34, in get
    res['data'] = data['data']
TypeError: string indices must be integers
[2019-11-18 10:52:47,516] [basehttp.py:124] [basehttp:log_message] [ERROR]- "GET /v1/users/user?page=2 HTTP/1.1" 500 81805
[2019-11-18 10:53:13,195] [basehttp.py:124] [basehttp:log_message] [INFO]- "GET /v1/users/user?page=2 HTTP/1.1" 200 958
[2019-11-18 10:53:29,793] [basehttp.py:124] [basehttp:log_message] [INFO]- "GET /v1/users/user?page=1 HTTP/1.1" 200 1107
[2019-11-18 10:59:04,224] [basehttp.py:124] [basehttp:log_message] [INFO]- "OPTIONS /v1/users/user?page=1 HTTP/1.1" 200 0
[2019-11-18 10:59:04,263] [basehttp.py:124] [basehttp:log_message] [INFO]- "GET /v1/users/user?page=1 HTTP/1.1" 200 1107
[2019-11-18 11:03:22,517] [basehttp.py:124] [basehttp:log_message] [INFO]- "GET /v1/users/user?page=1 HTTP/1.1" 200 1107
[2019-11-18 11:03:23,642] [basehttp.py:124] [basehttp:log_message] [INFO]- "GET /v1/users/user?page=1 HTTP/1.1" 200 1107
[2019-11-18 11:03:41,244] [basehttp.py:124] [basehttp:log_message] [INFO]- "GET /v1/users/user?page=1 HTTP/1.1" 200 1107
[2019-11-18 11:04:03,336] [basehttp.py:124] [basehttp:log_message] [INFO]- "GET /v1/users/user?page=1 HTTP/1.1" 200 1107
[2019-11-18 11:09:14,134] [basehttp.py:124] [basehttp:log_message] [INFO]- "GET /v1/users/user?page=1 HTTP/1.1" 200 1107
[2019-11-18 11:09:47,988] [basehttp.py:124] [basehttp:log_message] [INFO]- "GET /v1/users/user?page=1 HTTP/1.1" 200 1107
[2019-11-18 11:13:14,448] [basehttp.py:124] [basehttp:log_message] [INFO]- "GET /v1/users/user?page=1 HTTP/1.1" 200 1107
[2019-11-18 11:13:30,058] [basehttp.py:124] [basehttp:log_message] [INFO]- "GET /v1/users/user?page=1 HTTP/1.1" 200 1107
[2019-11-18 11:14:15,238] [basehttp.py:124] [basehttp:log_message] [INFO]- "GET /v1/users/user?page=1 HTTP/1.1" 200 1107
[2019-11-18 11:14:20,829] [basehttp.py:124] [basehttp:log_message] [INFO]- "GET /v1/users/user?page=1 HTTP/1.1" 200 1107
[2019-11-18 11:14:25,884] [basehttp.py:124] [basehttp:log_message] [INFO]- "GET /v1/users/user?page=1 HTTP/1.1" 200 1107
[2019-11-18 11:14:28,235] [basehttp.py:124] [basehttp:log_message] [INFO]- "GET /v1/users/user?page=1 HTTP/1.1" 200 1107
[2019-11-18 11:14:34,556] [basehttp.py:124] [basehttp:log_message] [INFO]- "GET /v1/users/user?page=1 HTTP/1.1" 200 1107
[2019-11-18 11:17:31,148] [basehttp.py:124] [basehttp:log_message] [INFO]- "GET /v1/users/user?page=1 HTTP/1.1" 200 1107
[2019-11-18 11:17:42,845] [basehttp.py:124] [basehttp:log_message] [INFO]- "GET /v1/users/user?page=1 HTTP/1.1" 200 1107
[2019-11-18 11:17:47,908] [basehttp.py:124] [basehttp:log_message] [INFO]- "GET /v1/users/user?page=1 HTTP/1.1" 200 1107
[2019-11-18 11:18:47,492] [basehttp.py:124] [basehttp:log_message] [INFO]- "GET /v1/users/user?page=1 HTTP/1.1" 200 1107
[2019-11-18 11:19:16,236] [basehttp.py:124] [basehttp:log_message] [INFO]- "GET /v1/users/user?page=1 HTTP/1.1" 200 1107
[2019-11-18 11:19:27,085] [basehttp.py:124] [basehttp:log_message] [INFO]- "GET /v1/users/user?page=1 HTTP/1.1" 200 1107
[2019-11-18 11:24:20,468] [basehttp.py:124] [basehttp:log_message] [INFO]- "GET /v1/users/user?page=1 HTTP/1.1" 200 1107
[2019-11-18 11:24:21,117] [basehttp.py:124] [basehttp:log_message] [INFO]- "GET /v1/users/user?page=1 HTTP/1.1" 200 1107
[2019-11-18 11:24:21,531] [basehttp.py:124] [basehttp:log_message] [INFO]- "GET /v1/users/user?page=1 HTTP/1.1" 200 1107
[2019-11-18 11:24:28,425] [basehttp.py:124] [basehttp:log_message] [INFO]- "GET /v1/users/user?page=1 HTTP/1.1" 200 1107
[2019-11-18 11:24:40,702] [basehttp.py:124] [basehttp:log_message] [INFO]- "GET /v1/users/user?page=1 HTTP/1.1" 200 1107
[2019-11-18 11:24:46,323] [basehttp.py:124] [basehttp:log_message] [INFO]- "GET /v1/users/user?page=1 HTTP/1.1" 200 1107
[2019-11-18 11:24:47,058] [basehttp.py:124] [basehttp:log_message] [INFO]- "GET /v1/users/user?page=1 HTTP/1.1" 200 1107
[2019-11-18 11:24:47,529] [basehttp.py:124] [basehttp:log_message] [INFO]- "GET /v1/users/user?page=1 HTTP/1.1" 200 1107
[2019-11-18 11:24:47,958] [basehttp.py:124] [basehttp:log_message] [INFO]- "GET /v1/users/user?page=1 HTTP/1.1" 200 1107
[2019-11-18 11:24:48,247] [basehttp.py:124] [basehttp:log_message] [INFO]- "GET /v1/users/user?page=1 HTTP/1.1" 200 1107
[2019-11-18 11:26:09,986] [basehttp.py:124] [basehttp:log_message] [INFO]- "GET /v1/users/user?page=1 HTTP/1.1" 200 1107
[2019-11-18 11:26:13,862] [basehttp.py:124] [basehttp:log_message] [INFO]- "GET /v1/users/user?page=1 HTTP/1.1" 200 1107
[2019-11-18 11:26:14,600] [basehttp.py:124] [basehttp:log_message] [INFO]- "GET /v1/users/user?page=1 HTTP/1.1" 200 1107
[2019-11-18 11:26:18,011] [basehttp.py:124] [basehttp:log_message] [INFO]- "GET /v1/users/user?page=1 HTTP/1.1" 200 1107
[2019-11-18 11:28:31,300] [basehttp.py:124] [basehttp:log_message] [INFO]- "GET /v1/users/user?page=1 HTTP/1.1" 200 1107
[2019-11-18 11:28:32,529] [basehttp.py:124] [basehttp:log_message] [INFO]- "GET /v1/users/user?page=1 HTTP/1.1" 200 1107
[2019-11-18 11:28:32,961] [basehttp.py:124] [basehttp:log_message] [INFO]- "GET /v1/users/user?page=1 HTTP/1.1" 200 1107
[2019-11-18 11:28:33,215] [basehttp.py:124] [basehttp:log_message] [INFO]- "GET /v1/users/user?page=1 HTTP/1.1" 200 1107
[2019-11-18 11:28:33,464] [basehttp.py:124] [basehttp:log_message] [INFO]- "GET /v1/users/user?page=1 HTTP/1.1" 200 1107
[2019-11-18 11:28:36,188] [basehttp.py:124] [basehttp:log_message] [INFO]- "GET /v1/users/user?page=1 HTTP/1.1" 200 1107
[2019-11-18 11:28:42,071] [basehttp.py:124] [basehttp:log_message] [INFO]- "GET /v1/users/user?page=1 HTTP/1.1" 200 1107
[2019-11-18 11:28:42,703] [basehttp.py:124] [basehttp:log_message] [INFO]- "GET /v1/users/user?page=1 HTTP/1.1" 200 1107
[2019-11-18 11:29:20,813] [basehttp.py:124] [basehttp:log_message] [INFO]- "GET /v1/users/user?page=1 HTTP/1.1" 200 1107
[2019-11-18 11:29:21,818] [basehttp.py:124] [basehttp:log_message] [INFO]- "GET /v1/users/user?page=1 HTTP/1.1" 200 1107
[2019-11-18 11:41:58,859] [basehttp.py:124] [basehttp:log_message] [INFO]- "GET /v1/users/user?page=1 HTTP/1.1" 200 1107
[2019-11-18 11:41:59,838] [basehttp.py:124] [basehttp:log_message] [INFO]- "GET /v1/users/user?page=1 HTTP/1.1" 200 1107
[2019-11-18 11:42:00,436] [basehttp.py:124] [basehttp:log_message] [INFO]- "GET /v1/users/user?page=1 HTTP/1.1" 200 1107
[2019-11-18 11:42:02,787] [basehttp.py:124] [basehttp:log_message] [INFO]- "GET /v1/users/user?page=1 HTTP/1.1" 200 1107
[2019-11-18 11:42:59,306] [basehttp.py:124] [basehttp:log_message] [INFO]- "GET /v1/users/user?page=1 HTTP/1.1" 200 1107
[2019-11-18 11:43:49,291] [basehttp.py:124] [basehttp:log_message] [INFO]- "GET /v1/users/user?page=1 HTTP/1.1" 200 1107
[2019-11-18 11:44:08,875] [basehttp.py:124] [basehttp:log_message] [INFO]- "GET /v1/users/user?page=1 HTTP/1.1" 200 1107
[2019-11-18 11:44:44,000] [basehttp.py:124] [basehttp:log_message] [INFO]- "OPTIONS /v1/users/user?page=1 HTTP/1.1" 200 0
[2019-11-18 11:44:44,012] [basehttp.py:124] [basehttp:log_message] [INFO]- "GET /v1/users/user?page=1 HTTP/1.1" 200 1107
[2019-11-18 11:44:53,284] [basehttp.py:124] [basehttp:log_message] [INFO]- "GET /v1/users/user?page=1 HTTP/1.1" 200 1107
[2019-11-18 11:44:54,020] [basehttp.py:124] [basehttp:log_message] [INFO]- "GET /v1/users/user?page=1 HTTP/1.1" 200 1107
[2019-11-18 11:44:55,514] [basehttp.py:124] [basehttp:log_message] [INFO]- "GET /v1/users/user?page=1 HTTP/1.1" 200 1107
[2019-11-18 11:45:36,031] [basehttp.py:124] [basehttp:log_message] [INFO]- "GET /v1/users/user?page=1 HTTP/1.1" 200 1107
[2019-11-18 11:45:36,661] [basehttp.py:124] [basehttp:log_message] [INFO]- "GET /v1/users/user?page=1 HTTP/1.1" 200 1107
[2019-11-18 11:45:36,847] [basehttp.py:124] [basehttp:log_message] [INFO]- "GET /v1/users/user?page=1 HTTP/1.1" 200 1107
[2019-11-18 11:45:44,172] [basehttp.py:124] [basehttp:log_message] [INFO]- "GET /v1/users/user?page=1 HTTP/1.1" 200 1107
[2019-11-18 11:45:45,152] [basehttp.py:124] [basehttp:log_message] [INFO]- "GET /v1/users/user?page=1 HTTP/1.1" 200 1107
[2019-11-18 11:46:00,385] [basehttp.py:124] [basehttp:log_message] [INFO]- "GET /v1/users/user?page=1 HTTP/1.1" 200 1107
[2019-11-18 11:46:00,907] [basehttp.py:124] [basehttp:log_message] [INFO]- "GET /v1/users/user?page=1 HTTP/1.1" 200 1107
[2019-11-18 11:46:02,828] [basehttp.py:124] [basehttp:log_message] [INFO]- "GET /v1/users/user?page=1 HTTP/1.1" 200 1107
[2019-11-18 11:46:20,684] [basehttp.py:124] [basehttp:log_message] [INFO]- "GET /v1/users/user?page=1 HTTP/1.1" 200 1107
[2019-11-18 11:46:31,897] [basehttp.py:124] [basehttp:log_message] [INFO]- "GET /v1/users/user?page=1 HTTP/1.1" 200 1107
[2019-11-18 11:47:56,109] [basehttp.py:124] [basehttp:log_message] [INFO]- "GET /v1/users/user?page=1 HTTP/1.1" 200 1107
[2019-11-18 11:48:02,029] [basehttp.py:124] [basehttp:log_message] [INFO]- "GET /v1/users/user?page=1 HTTP/1.1" 200 1107
[2019-11-18 11:48:10,512] [basehttp.py:124] [basehttp:log_message] [INFO]- "GET /v1/users/user?page=1 HTTP/1.1" 200 1107
[2019-11-18 11:49:14,192] [basehttp.py:124] [basehttp:log_message] [INFO]- "GET /v1/users/user?page=1 HTTP/1.1" 200 1107
[2019-11-18 11:49:46,467] [basehttp.py:124] [basehttp:log_message] [INFO]- "GET /v1/users/user?page=1 HTTP/1.1" 200 566
[2019-11-18 11:49:47,258] [basehttp.py:124] [basehttp:log_message] [INFO]- "GET /v1/users/user?page=1 HTTP/1.1" 200 566
[2019-11-18 11:49:47,784] [basehttp.py:124] [basehttp:log_message] [INFO]- "GET /v1/users/user?page=1 HTTP/1.1" 200 566
[2019-11-18 11:49:48,246] [basehttp.py:124] [basehttp:log_message] [INFO]- "GET /v1/users/user?page=1 HTTP/1.1" 200 566
[2019-11-18 11:49:48,799] [basehttp.py:124] [basehttp:log_message] [INFO]- "GET /v1/users/user?page=1 HTTP/1.1" 200 566
[2019-11-18 11:49:53,893] [basehttp.py:124] [basehttp:log_message] [INFO]- "GET /v1/users/user?page=1 HTTP/1.1" 200 566
[2019-11-18 11:49:54,774] [basehttp.py:124] [basehttp:log_message] [INFO]- "GET /v1/users/user?page=1 HTTP/1.1" 200 566
[2019-11-18 11:50:18,813] [basehttp.py:124] [basehttp:log_message] [INFO]- "GET /v1/users/user?page=1 HTTP/1.1" 200 566
[2019-11-18 11:50:26,625] [basehttp.py:124] [basehttp:log_message] [INFO]- "GET /v1/users/user?page=1 HTTP/1.1" 200 566
[2019-11-18 11:50:32,050] [basehttp.py:124] [basehttp:log_message] [INFO]- "GET /v1/users/user?page=1 HTTP/1.1" 200 566
[2019-11-18 11:50:39,614] [basehttp.py:124] [basehttp:log_message] [INFO]- "GET /v1/users/user?page=1 HTTP/1.1" 200 566
[2019-11-18 11:50:49,333] [basehttp.py:124] [basehttp:log_message] [INFO]- "GET /v1/users/user?page=1 HTTP/1.1" 200 566
[2019-11-18 11:53:56,474] [basehttp.py:124] [basehttp:log_message] [INFO]- "GET /v1/users/user?page=1 HTTP/1.1" 200 566
[2019-11-18 11:54:00,431] [basehttp.py:124] [basehttp:log_message] [INFO]- "GET /v1/users/user?page=1 HTTP/1.1" 200 566
[2019-11-18 11:56:47,861] [basehttp.py:124] [basehttp:log_message] [INFO]- "GET /v1/users/user?page=1 HTTP/1.1" 200 566
[2019-11-18 11:57:42,690] [basehttp.py:124] [basehttp:log_message] [INFO]- "GET /v1/users/user?page=1 HTTP/1.1" 200 566
[2019-11-18 11:57:43,612] [basehttp.py:124] [basehttp:log_message] [INFO]- "GET /v1/users/user?page=1 HTTP/1.1" 200 566
[2019-11-18 12:06:16,734] [basehttp.py:124] [basehttp:log_message] [INFO]- "GET /v1/users/user?page=1 HTTP/1.1" 200 566
[2019-11-18 12:07:59,575] [basehttp.py:124] [basehttp:log_message] [INFO]- "GET /v1/users/user?page=1 HTTP/1.1" 200 566
[2019-11-18 12:08:05,072] [basehttp.py:124] [basehttp:log_message] [INFO]- "GET /v1/users/user?page=1 HTTP/1.1" 200 566
[2019-11-18 12:08:48,111] [basehttp.py:124] [basehttp:log_message] [INFO]- "GET /v1/users/user?page=1 HTTP/1.1" 200 566
[2019-11-18 12:08:49,249] [basehttp.py:124] [basehttp:log_message] [INFO]- "OPTIONS /v1/users/user?page=0 HTTP/1.1" 200 0
[2019-11-18 12:08:49,258] [views.py:40] [views:get] [ERROR]- 添加失败：页号少于1
[2019-11-18 12:08:49,272] [basehttp.py:124] [basehttp:log_message] [INFO]- "GET /v1/users/user?page=0 HTTP/1.1" 200 51
[2019-11-18 12:09:05,117] [basehttp.py:124] [basehttp:log_message] [INFO]- "GET /v1/users/user?page=1 HTTP/1.1" 200 566
[2019-11-18 12:09:08,445] [views.py:40] [views:get] [ERROR]- 添加失败：页号少于1
[2019-11-18 12:09:08,447] [basehttp.py:124] [basehttp:log_message] [INFO]- "GET /v1/users/user?page=0 HTTP/1.1" 200 51
[2019-11-18 12:09:16,055] [views.py:40] [views:get] [ERROR]- 添加失败：页号少于1
[2019-11-18 12:09:16,056] [basehttp.py:124] [basehttp:log_message] [INFO]- "GET /v1/users/user?page=0 HTTP/1.1" 200 51
[2019-11-18 12:11:05,417] [views.py:40] [views:get] [ERROR]- 添加失败：页号少于1
[2019-11-18 12:11:05,418] [basehttp.py:124] [basehttp:log_message] [INFO]- "GET /v1/users/user?page=0 HTTP/1.1" 200 51
[2019-11-18 12:11:35,437] [basehttp.py:124] [basehttp:log_message] [INFO]- "GET /v1/users/user?page=1 HTTP/1.1" 200 566
[2019-11-18 12:11:36,152] [views.py:40] [views:get] [ERROR]- 添加失败：页号少于1
[2019-11-18 12:11:36,153] [basehttp.py:124] [basehttp:log_message] [INFO]- "GET /v1/users/user?page=0 HTTP/1.1" 200 51
[2019-11-18 12:11:38,804] [views.py:40] [views:get] [ERROR]- 添加失败：页号少于1
[2019-11-18 12:11:38,805] [basehttp.py:124] [basehttp:log_message] [INFO]- "GET /v1/users/user?page=0 HTTP/1.1" 200 51
[2019-11-18 12:12:20,380] [views.py:40] [views:get] [ERROR]- 添加失败：页号少于1
[2019-11-18 12:12:20,382] [basehttp.py:124] [basehttp:log_message] [INFO]- "GET /v1/users/user?page=0 HTTP/1.1" 200 51
[2019-11-18 12:12:24,047] [views.py:40] [views:get] [ERROR]- 添加失败：页号少于1
[2019-11-18 12:12:24,048] [basehttp.py:124] [basehttp:log_message] [INFO]- "GET /v1/users/user?page=0 HTTP/1.1" 200 51
[2019-11-18 12:13:09,356] [basehttp.py:124] [basehttp:log_message] [INFO]- "GET /v1/users/user?page=1 HTTP/1.1" 200 566
[2019-11-18 12:13:10,392] [views.py:40] [views:get] [ERROR]- 添加失败：页号少于1
[2019-11-18 12:13:10,393] [basehttp.py:124] [basehttp:log_message] [INFO]- "GET /v1/users/user?page=0 HTTP/1.1" 200 51
[2019-11-18 12:13:19,672] [views.py:40] [views:get] [ERROR]- 添加失败：页号少于1
[2019-11-18 12:13:19,673] [basehttp.py:124] [basehttp:log_message] [INFO]- "GET /v1/users/user?page=0 HTTP/1.1" 200 51
[2019-11-18 12:13:40,202] [basehttp.py:124] [basehttp:log_message] [INFO]- "GET /v1/users/user?page=1 HTTP/1.1" 200 566
[2019-11-18 12:13:41,227] [views.py:40] [views:get] [ERROR]- 添加失败：页号少于1
[2019-11-18 12:13:41,228] [basehttp.py:124] [basehttp:log_message] [INFO]- "GET /v1/users/user?page=0 HTTP/1.1" 200 51
[2019-11-18 12:13:53,302] [views.py:40] [views:get] [ERROR]- 添加失败：页号少于1
[2019-11-18 12:13:53,303] [basehttp.py:124] [basehttp:log_message] [INFO]- "GET /v1/users/user?page=0 HTTP/1.1" 200 51
[2019-11-18 12:29:19,839] [basehttp.py:124] [basehttp:log_message] [INFO]- "GET /v1/users/user?page=1 HTTP/1.1" 200 566
[2019-11-18 12:29:20,866] [basehttp.py:124] [basehttp:log_message] [INFO]- "GET /v1/users/user?page=1 HTTP/1.1" 200 566
[2019-11-18 12:29:21,816] [basehttp.py:124] [basehttp:log_message] [INFO]- "GET /v1/users/user?page=1 HTTP/1.1" 200 566
[2019-11-18 12:29:22,315] [basehttp.py:124] [basehttp:log_message] [INFO]- "GET /v1/users/user?page=1 HTTP/1.1" 200 566
[2019-11-18 12:29:23,684] [basehttp.py:124] [basehttp:log_message] [INFO]- "GET /v1/users/user?page=1 HTTP/1.1" 200 566
[2019-11-18 12:29:25,245] [basehttp.py:124] [basehttp:log_message] [INFO]- "GET /v1/users/user?page=1 HTTP/1.1" 200 566
[2019-11-18 12:29:26,159] [basehttp.py:124] [basehttp:log_message] [INFO]- "GET /v1/users/user?page=1 HTTP/1.1" 200 566
[2019-11-18 12:29:26,816] [basehttp.py:124] [basehttp:log_message] [INFO]- "GET /v1/users/user?page=1 HTTP/1.1" 200 566
[2019-11-18 12:29:27,220] [basehttp.py:124] [basehttp:log_message] [INFO]- "GET /v1/users/user?page=1 HTTP/1.1" 200 566
[2019-11-18 12:29:27,756] [basehttp.py:124] [basehttp:log_message] [INFO]- "GET /v1/users/user?page=1 HTTP/1.1" 200 566
[2019-11-18 12:29:28,271] [basehttp.py:124] [basehttp:log_message] [INFO]- "GET /v1/users/user?page=1 HTTP/1.1" 200 566
[2019-11-18 12:29:28,680] [basehttp.py:124] [basehttp:log_message] [INFO]- "GET /v1/users/user?page=1 HTTP/1.1" 200 566
[2019-11-18 12:29:29,061] [basehttp.py:124] [basehttp:log_message] [INFO]- "GET /v1/users/user?page=1 HTTP/1.1" 200 566
[2019-11-18 12:29:29,375] [basehttp.py:124] [basehttp:log_message] [INFO]- "GET /v1/users/user?page=1 HTTP/1.1" 200 566
[2019-11-18 12:29:50,127] [basehttp.py:124] [basehttp:log_message] [INFO]- "GET /v1/users/user?page=1 HTTP/1.1" 200 566
[2019-11-18 12:29:50,791] [basehttp.py:124] [basehttp:log_message] [INFO]- "OPTIONS /v1/users/user?page=3 HTTP/1.1" 200 0
[2019-11-18 12:29:50,802] [basehttp.py:124] [basehttp:log_message] [INFO]- "GET /v1/users/user?page=3 HTTP/1.1" 200 574
[2019-11-18 12:29:53,210] [basehttp.py:124] [basehttp:log_message] [INFO]- "OPTIONS /v1/users/user?page=4 HTTP/1.1" 200 0
[2019-11-18 12:29:53,229] [basehttp.py:124] [basehttp:log_message] [INFO]- "GET /v1/users/user?page=4 HTTP/1.1" 200 433
[2019-11-18 12:29:53,988] [basehttp.py:124] [basehttp:log_message] [INFO]- "GET /v1/users/user?page=3 HTTP/1.1" 200 574
[2019-11-18 12:29:54,475] [basehttp.py:124] [basehttp:log_message] [INFO]- "OPTIONS /v1/users/user?page=2 HTTP/1.1" 200 0
[2019-11-18 12:29:54,491] [basehttp.py:124] [basehttp:log_message] [INFO]- "GET /v1/users/user?page=2 HTTP/1.1" 200 590
[2019-11-18 12:29:55,081] [basehttp.py:124] [basehttp:log_message] [INFO]- "GET /v1/users/user?page=3 HTTP/1.1" 200 574
[2019-11-18 12:29:55,473] [basehttp.py:124] [basehttp:log_message] [INFO]- "GET /v1/users/user?page=4 HTTP/1.1" 200 433
[2019-11-18 12:29:55,868] [basehttp.py:124] [basehttp:log_message] [INFO]- "GET /v1/users/user?page=3 HTTP/1.1" 200 574
[2019-11-18 12:29:56,284] [basehttp.py:124] [basehttp:log_message] [INFO]- "GET /v1/users/user?page=2 HTTP/1.1" 200 590
[2019-11-18 12:29:57,162] [basehttp.py:124] [basehttp:log_message] [INFO]- "GET /v1/users/user?page=1 HTTP/1.1" 200 566
[2019-11-18 12:29:57,544] [basehttp.py:124] [basehttp:log_message] [INFO]- "GET /v1/users/user?page=3 HTTP/1.1" 200 574
[2019-11-18 12:29:57,839] [basehttp.py:124] [basehttp:log_message] [INFO]- "GET /v1/users/user?page=4 HTTP/1.1" 200 433
[2019-11-18 12:29:58,313] [basehttp.py:124] [basehttp:log_message] [INFO]- "GET /v1/users/user?page=3 HTTP/1.1" 200 574
[2019-11-18 12:29:59,802] [basehttp.py:124] [basehttp:log_message] [INFO]- "GET /v1/users/user?page=4 HTTP/1.1" 200 433
[2019-11-18 12:30:00,297] [basehttp.py:124] [basehttp:log_message] [INFO]- "GET /v1/users/user?page=3 HTTP/1.1" 200 574
[2019-11-18 12:30:00,676] [basehttp.py:124] [basehttp:log_message] [INFO]- "GET /v1/users/user?page=2 HTTP/1.1" 200 590
[2019-11-18 12:30:01,024] [basehttp.py:124] [basehttp:log_message] [INFO]- "GET /v1/users/user?page=1 HTTP/1.1" 200 566
[2019-11-18 12:30:01,337] [basehttp.py:124] [basehttp:log_message] [INFO]- "GET /v1/users/user?page=3 HTTP/1.1" 200 574
[2019-11-18 12:30:02,073] [basehttp.py:124] [basehttp:log_message] [INFO]- "GET /v1/users/user?page=2 HTTP/1.1" 200 590
[2019-11-18 12:30:02,515] [basehttp.py:124] [basehttp:log_message] [INFO]- "GET /v1/users/user?page=3 HTTP/1.1" 200 574
[2019-11-18 12:30:02,857] [basehttp.py:124] [basehttp:log_message] [INFO]- "GET /v1/users/user?page=4 HTTP/1.1" 200 433
[2019-11-18 12:30:03,232] [basehttp.py:124] [basehttp:log_message] [INFO]- "GET /v1/users/user?page=3 HTTP/1.1" 200 574
[2019-11-18 12:30:03,588] [basehttp.py:124] [basehttp:log_message] [INFO]- "GET /v1/users/user?page=2 HTTP/1.1" 200 590
[2019-11-18 12:30:03,956] [basehttp.py:124] [basehttp:log_message] [INFO]- "GET /v1/users/user?page=1 HTTP/1.1" 200 566
[2019-11-18 12:30:04,337] [basehttp.py:124] [basehttp:log_message] [INFO]- "GET /v1/users/user?page=2 HTTP/1.1" 200 590
[2019-11-18 12:30:04,693] [basehttp.py:124] [basehttp:log_message] [INFO]- "GET /v1/users/user?page=3 HTTP/1.1" 200 574
[2019-11-18 12:30:05,068] [basehttp.py:124] [basehttp:log_message] [INFO]- "GET /v1/users/user?page=4 HTTP/1.1" 200 433
[2019-11-18 12:30:05,418] [basehttp.py:124] [basehttp:log_message] [INFO]- "GET /v1/users/user?page=3 HTTP/1.1" 200 574
[2019-11-18 12:30:05,795] [basehttp.py:124] [basehttp:log_message] [INFO]- "GET /v1/users/user?page=2 HTTP/1.1" 200 590
[2019-11-18 12:30:06,182] [basehttp.py:124] [basehttp:log_message] [INFO]- "GET /v1/users/user?page=1 HTTP/1.1" 200 566
[2019-11-18 12:30:07,373] [basehttp.py:124] [basehttp:log_message] [INFO]- "GET /v1/users/user?page=2 HTTP/1.1" 200 590
[2019-11-18 12:30:07,834] [basehttp.py:124] [basehttp:log_message] [INFO]- "GET /v1/users/user?page=3 HTTP/1.1" 200 574
[2019-11-18 12:30:08,392] [basehttp.py:124] [basehttp:log_message] [INFO]- "GET /v1/users/user?page=4 HTTP/1.1" 200 433
[2019-11-18 12:30:25,708] [basehttp.py:124] [basehttp:log_message] [INFO]- "GET /v1/users/user?page=1 HTTP/1.1" 200 566
[2019-11-18 12:30:26,945] [basehttp.py:124] [basehttp:log_message] [INFO]- "GET /v1/users/user?page=3 HTTP/1.1" 200 574
[2019-11-18 12:30:27,564] [basehttp.py:124] [basehttp:log_message] [INFO]- "GET /v1/users/user?page=2 HTTP/1.1" 200 590
[2019-11-18 12:30:28,107] [basehttp.py:124] [basehttp:log_message] [INFO]- "GET /v1/users/user?page=1 HTTP/1.1" 200 566
[2019-11-18 12:30:29,809] [basehttp.py:124] [basehttp:log_message] [INFO]- "GET /v1/users/user?page=2 HTTP/1.1" 200 590
[2019-11-18 12:30:30,275] [basehttp.py:124] [basehttp:log_message] [INFO]- "GET /v1/users/user?page=3 HTTP/1.1" 200 574
[2019-11-18 12:30:30,646] [basehttp.py:124] [basehttp:log_message] [INFO]- "GET /v1/users/user?page=4 HTTP/1.1" 200 433
[2019-11-18 12:30:35,279] [basehttp.py:124] [basehttp:log_message] [INFO]- "GET /v1/users/user?page=3 HTTP/1.1" 200 574
[2019-11-18 12:30:35,854] [basehttp.py:124] [basehttp:log_message] [INFO]- "GET /v1/users/user?page=2 HTTP/1.1" 200 590
[2019-11-18 12:30:36,321] [basehttp.py:124] [basehttp:log_message] [INFO]- "GET /v1/users/user?page=1 HTTP/1.1" 200 566
[2019-11-18 12:30:38,322] [basehttp.py:124] [basehttp:log_message] [INFO]- "GET /v1/users/user?page=2 HTTP/1.1" 200 590
[2019-11-18 12:30:38,474] [basehttp.py:124] [basehttp:log_message] [INFO]- "GET /v1/users/user?page=3 HTTP/1.1" 200 574
[2019-11-18 12:30:38,656] [basehttp.py:124] [basehttp:log_message] [INFO]- "GET /v1/users/user?page=4 HTTP/1.1" 200 433
[2019-11-18 12:30:39,685] [basehttp.py:124] [basehttp:log_message] [INFO]- "GET /v1/users/user?page=3 HTTP/1.1" 200 574
[2019-11-18 12:30:39,864] [basehttp.py:124] [basehttp:log_message] [INFO]- "GET /v1/users/user?page=2 HTTP/1.1" 200 590
[2019-11-18 12:30:40,037] [basehttp.py:124] [basehttp:log_message] [INFO]- "GET /v1/users/user?page=1 HTTP/1.1" 200 566
[2019-11-18 12:30:44,684] [basehttp.py:124] [basehttp:log_message] [INFO]- "GET /v1/users/user?page=1 HTTP/1.1" 200 566
[2019-11-18 12:30:50,223] [basehttp.py:124] [basehttp:log_message] [INFO]- "GET /v1/users/user?page=2 HTTP/1.1" 200 590
[2019-11-18 12:30:50,548] [basehttp.py:124] [basehttp:log_message] [INFO]- "GET /v1/users/user?page=3 HTTP/1.1" 200 574
[2019-11-18 12:30:50,726] [basehttp.py:124] [basehttp:log_message] [INFO]- "GET /v1/users/user?page=4 HTTP/1.1" 200 433
[2019-11-18 12:30:55,246] [basehttp.py:124] [basehttp:log_message] [INFO]- "GET /v1/users/user?page=2 HTTP/1.1" 200 590
[2019-11-18 12:31:14,342] [basehttp.py:124] [basehttp:log_message] [INFO]- "GET /v1/users/user?page=1 HTTP/1.1" 200 1107
[2019-11-18 12:31:16,268] [basehttp.py:124] [basehttp:log_message] [INFO]- "GET /v1/users/user?page=2 HTTP/1.1" 200 958
[2019-11-18 12:31:16,992] [basehttp.py:124] [basehttp:log_message] [INFO]- "GET /v1/users/user?page=1 HTTP/1.1" 200 1107
[2019-11-18 12:31:17,557] [basehttp.py:124] [basehttp:log_message] [INFO]- "GET /v1/users/user?page=2 HTTP/1.1" 200 958
[2019-11-18 12:31:18,116] [basehttp.py:124] [basehttp:log_message] [INFO]- "GET /v1/users/user?page=1 HTTP/1.1" 200 1107
[2019-11-18 12:31:18,550] [basehttp.py:124] [basehttp:log_message] [INFO]- "GET /v1/users/user?page=2 HTTP/1.1" 200 958
[2019-11-18 12:31:18,995] [basehttp.py:124] [basehttp:log_message] [INFO]- "GET /v1/users/user?page=1 HTTP/1.1" 200 1107
[2019-11-18 12:31:19,428] [basehttp.py:124] [basehttp:log_message] [INFO]- "GET /v1/users/user?page=2 HTTP/1.1" 200 958
[2019-11-18 12:31:19,901] [basehttp.py:124] [basehttp:log_message] [INFO]- "GET /v1/users/user?page=1 HTTP/1.1" 200 1107
[2019-11-18 12:31:20,316] [basehttp.py:124] [basehttp:log_message] [INFO]- "GET /v1/users/user?page=2 HTTP/1.1" 200 958
[2019-11-18 12:31:20,696] [basehttp.py:124] [basehttp:log_message] [INFO]- "GET /v1/users/user?page=1 HTTP/1.1" 200 1107
[2019-11-18 12:31:21,100] [basehttp.py:124] [basehttp:log_message] [INFO]- "GET /v1/users/user?page=2 HTTP/1.1" 200 958
[2019-11-18 12:31:22,400] [basehttp.py:124] [basehttp:log_message] [INFO]- "GET /v1/users/user?page=1 HTTP/1.1" 200 1107
[2019-11-18 12:32:33,028] [basehttp.py:124] [basehttp:log_message] [INFO]- "GET /v1/users/user?page=1 HTTP/1.1" 200 1107
[2019-11-18 12:32:34,156] [basehttp.py:124] [basehttp:log_message] [INFO]- "GET /v1/users/user?page=1 HTTP/1.1" 200 1107
[2019-11-18 12:32:34,580] [basehttp.py:124] [basehttp:log_message] [INFO]- "GET /v1/users/user?page=1 HTTP/1.1" 200 1107
[2019-11-18 12:32:35,152] [basehttp.py:124] [basehttp:log_message] [INFO]- "GET /v1/users/user?page=1 HTTP/1.1" 200 1107
[2019-11-18 12:32:35,630] [basehttp.py:124] [basehttp:log_message] [INFO]- "GET /v1/users/user?page=1 HTTP/1.1" 200 1107
[2019-11-18 12:32:35,919] [basehttp.py:124] [basehttp:log_message] [INFO]- "GET /v1/users/user?page=1 HTTP/1.1" 200 1107
[2019-11-18 12:32:36,407] [basehttp.py:124] [basehttp:log_message] [INFO]- "GET /v1/users/user?page=1 HTTP/1.1" 200 1107
[2019-11-18 12:32:36,785] [basehttp.py:124] [basehttp:log_message] [INFO]- "GET /v1/users/user?page=1 HTTP/1.1" 200 1107
[2019-11-18 12:32:37,216] [basehttp.py:124] [basehttp:log_message] [INFO]- "GET /v1/users/user?page=1 HTTP/1.1" 200 1107
[2019-11-18 12:32:37,619] [basehttp.py:124] [basehttp:log_message] [INFO]- "GET /v1/users/user?page=1 HTTP/1.1" 200 1107
[2019-11-18 12:32:38,049] [basehttp.py:124] [basehttp:log_message] [INFO]- "GET /v1/users/user?page=1 HTTP/1.1" 200 1107
[2019-11-18 12:32:38,526] [basehttp.py:124] [basehttp:log_message] [INFO]- "GET /v1/users/user?page=1 HTTP/1.1" 200 1107
[2019-11-18 12:32:38,915] [basehttp.py:124] [basehttp:log_message] [INFO]- "GET /v1/users/user?page=1 HTTP/1.1" 200 1107
[2019-11-18 12:32:56,976] [basehttp.py:124] [basehttp:log_message] [INFO]- "OPTIONS /v1/users/user?page=1 HTTP/1.1" 200 0
[2019-11-18 12:32:56,993] [basehttp.py:124] [basehttp:log_message] [INFO]- "GET /v1/users/user?page=1 HTTP/1.1" 200 1107
[2019-11-18 12:34:04,028] [basehttp.py:124] [basehttp:log_message] [INFO]- "GET /v1/users/user?page=1 HTTP/1.1" 200 1107
[2019-11-18 12:34:04,436] [basehttp.py:124] [basehttp:log_message] [INFO]- "GET /v1/users/user?page=1 HTTP/1.1" 200 1107
[2019-11-18 12:34:04,758] [basehttp.py:124] [basehttp:log_message] [INFO]- "GET /v1/users/user?page=1 HTTP/1.1" 200 1107
[2019-11-18 12:34:05,040] [basehttp.py:124] [basehttp:log_message] [INFO]- "GET /v1/users/user?page=1 HTTP/1.1" 200 1107
[2019-11-18 12:34:05,306] [basehttp.py:124] [basehttp:log_message] [INFO]- "GET /v1/users/user?page=1 HTTP/1.1" 200 1107
[2019-11-18 12:34:05,594] [basehttp.py:124] [basehttp:log_message] [INFO]- "GET /v1/users/user?page=1 HTTP/1.1" 200 1107
[2019-11-18 12:34:05,870] [basehttp.py:124] [basehttp:log_message] [INFO]- "GET /v1/users/user?page=1 HTTP/1.1" 200 1107
[2019-11-18 12:34:06,240] [basehttp.py:124] [basehttp:log_message] [INFO]- "GET /v1/users/user?page=1 HTTP/1.1" 200 1107
[2019-11-18 12:34:06,676] [basehttp.py:124] [basehttp:log_message] [INFO]- "GET /v1/users/user?page=1 HTTP/1.1" 200 1107
[2019-11-18 12:34:06,992] [basehttp.py:124] [basehttp:log_message] [INFO]- "GET /v1/users/user?page=1 HTTP/1.1" 200 1107
[2019-11-18 12:34:07,270] [basehttp.py:124] [basehttp:log_message] [INFO]- "GET /v1/users/user?page=1 HTTP/1.1" 200 1107
[2019-11-18 12:34:07,492] [basehttp.py:124] [basehttp:log_message] [INFO]- "GET /v1/users/user?page=1 HTTP/1.1" 200 1107
[2019-11-18 12:34:07,733] [basehttp.py:124] [basehttp:log_message] [INFO]- "GET /v1/users/user?page=1 HTTP/1.1" 200 1107
[2019-11-18 12:34:07,938] [basehttp.py:124] [basehttp:log_message] [INFO]- "GET /v1/users/user?page=1 HTTP/1.1" 200 1107
[2019-11-18 12:34:09,642] [basehttp.py:124] [basehttp:log_message] [INFO]- "GET /v1/users/user?page=1 HTTP/1.1" 200 1107
[2019-11-18 12:34:09,957] [basehttp.py:124] [basehttp:log_message] [INFO]- "GET /v1/users/user?page=1 HTTP/1.1" 200 1107
[2019-11-18 12:34:10,147] [basehttp.py:124] [basehttp:log_message] [INFO]- "GET /v1/users/user?page=1 HTTP/1.1" 200 1107
[2019-11-18 12:34:44,489] [basehttp.py:124] [basehttp:log_message] [INFO]- "GET /v1/users/user?page=1 HTTP/1.1" 200 1107
[2019-11-18 12:34:45,093] [basehttp.py:124] [basehttp:log_message] [INFO]- "GET /v1/users/user?page=1 HTTP/1.1" 200 1107
[2019-11-18 12:34:45,508] [basehttp.py:124] [basehttp:log_message] [INFO]- "GET /v1/users/user?page=1 HTTP/1.1" 200 1107
[2019-11-18 12:34:50,130] [basehttp.py:124] [basehttp:log_message] [INFO]- "OPTIONS /v1/users/user?page=2 HTTP/1.1" 200 0
[2019-11-18 12:34:50,146] [basehttp.py:124] [basehttp:log_message] [INFO]- "GET /v1/users/user?page=2 HTTP/1.1" 200 958
[2019-11-18 12:34:51,009] [basehttp.py:124] [basehttp:log_message] [INFO]- "GET /v1/users/user?page=1 HTTP/1.1" 200 1107
[2019-11-18 12:35:03,330] [basehttp.py:124] [basehttp:log_message] [INFO]- "GET /v1/users/user?page=2 HTTP/1.1" 200 958
[2019-11-18 12:35:04,607] [basehttp.py:124] [basehttp:log_message] [INFO]- "GET /v1/users/user?page=1 HTTP/1.1" 200 1107
[2019-11-18 12:35:05,612] [basehttp.py:124] [basehttp:log_message] [INFO]- "GET /v1/users/user?page=2 HTTP/1.1" 200 958
[2019-11-18 12:35:06,198] [basehttp.py:124] [basehttp:log_message] [INFO]- "GET /v1/users/user?page=1 HTTP/1.1" 200 1107
[2019-11-18 12:35:06,924] [basehttp.py:124] [basehttp:log_message] [INFO]- "GET /v1/users/user?page=2 HTTP/1.1" 200 958
[2019-11-18 12:35:07,620] [basehttp.py:124] [basehttp:log_message] [INFO]- "GET /v1/users/user?page=1 HTTP/1.1" 200 1107
[2019-11-18 12:35:07,926] [basehttp.py:124] [basehttp:log_message] [INFO]- "GET /v1/users/user?page=2 HTTP/1.1" 200 958
[2019-11-18 12:35:08,821] [basehttp.py:124] [basehttp:log_message] [INFO]- "GET /v1/users/user?page=1 HTTP/1.1" 200 1107
[2019-11-18 12:35:09,153] [basehttp.py:124] [basehttp:log_message] [INFO]- "GET /v1/users/user?page=2 HTTP/1.1" 200 958
[2019-11-18 12:35:09,507] [basehttp.py:124] [basehttp:log_message] [INFO]- "GET /v1/users/user?page=1 HTTP/1.1" 200 1107
[2019-11-18 12:35:09,869] [basehttp.py:124] [basehttp:log_message] [INFO]- "GET /v1/users/user?page=2 HTTP/1.1" 200 958
[2019-11-18 12:35:10,190] [basehttp.py:124] [basehttp:log_message] [INFO]- "GET /v1/users/user?page=1 HTTP/1.1" 200 1107
[2019-11-18 12:35:10,505] [basehttp.py:124] [basehttp:log_message] [INFO]- "GET /v1/users/user?page=2 HTTP/1.1" 200 958
[2019-11-18 12:35:10,812] [basehttp.py:124] [basehttp:log_message] [INFO]- "GET /v1/users/user?page=1 HTTP/1.1" 200 1107
[2019-11-18 12:35:11,141] [basehttp.py:124] [basehttp:log_message] [INFO]- "GET /v1/users/user?page=2 HTTP/1.1" 200 958
[2019-11-18 12:35:11,437] [basehttp.py:124] [basehttp:log_message] [INFO]- "GET /v1/users/user?page=1 HTTP/1.1" 200 1107
[2019-11-18 12:35:11,699] [basehttp.py:124] [basehttp:log_message] [INFO]- "GET /v1/users/user?page=2 HTTP/1.1" 200 958
[2019-11-18 12:35:12,014] [basehttp.py:124] [basehttp:log_message] [INFO]- "GET /v1/users/user?page=1 HTTP/1.1" 200 1107
[2019-11-18 12:35:12,364] [basehttp.py:124] [basehttp:log_message] [INFO]- "GET /v1/users/user?page=2 HTTP/1.1" 200 958
[2019-11-18 12:35:53,463] [basehttp.py:124] [basehttp:log_message] [INFO]- "GET /v1/users/user?page=1 HTTP/1.1" 200 1107
[2019-11-18 12:35:54,017] [basehttp.py:124] [basehttp:log_message] [INFO]- "GET /v1/users/user?page=2 HTTP/1.1" 200 958
[2019-11-18 12:36:10,562] [basehttp.py:124] [basehttp:log_message] [INFO]- "GET /v1/users/user?page=1 HTTP/1.1" 200 1107
[2019-11-18 12:36:13,926] [basehttp.py:124] [basehttp:log_message] [INFO]- "GET /v1/users/user?page=1 HTTP/1.1" 200 1107
[2019-11-18 12:36:17,436] [basehttp.py:124] [basehttp:log_message] [INFO]- "GET /v1/users/user?page=1 HTTP/1.1" 200 1107
[2019-11-18 12:36:17,984] [basehttp.py:124] [basehttp:log_message] [INFO]- "GET /v1/users/user?page=1 HTTP/1.1" 200 1107
[2019-11-18 12:36:18,245] [basehttp.py:124] [basehttp:log_message] [INFO]- "GET /v1/users/user?page=1 HTTP/1.1" 200 1107
[2019-11-18 12:36:18,456] [basehttp.py:124] [basehttp:log_message] [INFO]- "GET /v1/users/user?page=1 HTTP/1.1" 200 1107
[2019-11-18 12:36:21,678] [basehttp.py:124] [basehttp:log_message] [INFO]- "GET /v1/users/user?page=1 HTTP/1.1" 200 1107
[2019-11-18 12:36:25,983] [basehttp.py:124] [basehttp:log_message] [INFO]- "GET /v1/users/user?page=1 HTTP/1.1" 200 1107
[2019-11-18 12:36:26,622] [basehttp.py:124] [basehttp:log_message] [INFO]- "GET /v1/users/user?page=1 HTTP/1.1" 200 1107
[2019-11-18 12:36:31,177] [basehttp.py:124] [basehttp:log_message] [INFO]- "GET /v1/users/user?page=1 HTTP/1.1" 200 1107
[2019-11-18 12:36:31,667] [basehttp.py:124] [basehttp:log_message] [INFO]- "GET /v1/users/user?page=1 HTTP/1.1" 200 1107
[2019-11-18 12:36:35,979] [basehttp.py:124] [basehttp:log_message] [INFO]- "GET /v1/users/user?page=1 HTTP/1.1" 200 1107
[2019-11-18 12:36:36,496] [basehttp.py:124] [basehttp:log_message] [INFO]- "GET /v1/users/user?page=1 HTTP/1.1" 200 1107
[2019-11-18 12:42:50,498] [basehttp.py:124] [basehttp:log_message] [INFO]- "GET /v1/users/user?page=1 HTTP/1.1" 200 1107
[2019-11-18 12:42:51,297] [basehttp.py:124] [basehttp:log_message] [INFO]- "GET /v1/users/user?page=1 HTTP/1.1" 200 1107
[2019-11-18 12:42:52,631] [basehttp.py:124] [basehttp:log_message] [INFO]- "GET /v1/users/user?page=2 HTTP/1.1" 200 958
[2019-11-18 12:42:53,133] [basehttp.py:124] [basehttp:log_message] [INFO]- "GET /v1/users/user?page=1 HTTP/1.1" 200 1107
[2019-11-18 13:06:01,230] [basehttp.py:124] [basehttp:log_message] [INFO]- "GET /v1/users/user?page=1 HTTP/1.1" 200 1107
[2019-11-18 13:06:01,846] [basehttp.py:124] [basehttp:log_message] [INFO]- "GET /v1/users/user?page=1 HTTP/1.1" 200 1107
[2019-11-18 13:06:14,357] [basehttp.py:124] [basehttp:log_message] [INFO]- "GET /v1/users/user?page=1 HTTP/1.1" 200 1107
[2019-11-18 13:06:17,808] [basehttp.py:124] [basehttp:log_message] [INFO]- "GET /v1/users/user?page=2 HTTP/1.1" 200 958
[2019-11-18 13:06:18,727] [basehttp.py:124] [basehttp:log_message] [INFO]- "GET /v1/users/user?page=1 HTTP/1.1" 200 1107
[2019-11-18 13:06:19,989] [basehttp.py:124] [basehttp:log_message] [INFO]- "GET /v1/users/user?page=2 HTTP/1.1" 200 958
[2019-11-18 13:06:20,817] [basehttp.py:124] [basehttp:log_message] [INFO]- "GET /v1/users/user?page=1 HTTP/1.1" 200 1107
[2019-11-18 13:06:21,598] [basehttp.py:124] [basehttp:log_message] [INFO]- "GET /v1/users/user?page=2 HTTP/1.1" 200 958
[2019-11-18 13:06:22,611] [basehttp.py:124] [basehttp:log_message] [INFO]- "GET /v1/users/user?page=1 HTTP/1.1" 200 1107
[2019-11-18 13:07:37,046] [basehttp.py:124] [basehttp:log_message] [INFO]- "GET /v1/users/user?page=1 HTTP/1.1" 200 1107
[2019-11-18 13:07:39,978] [basehttp.py:124] [basehttp:log_message] [INFO]- "GET /v1/users/user?page=2 HTTP/1.1" 200 958
[2019-11-18 13:10:29,896] [exception.py:135] [exception:handle_uncaught_exception] [ERROR]- Internal Server Error: /v1/users/user
Traceback (most recent call last):
  File "/home/tarena/.local/lib/python3.6/site-packages/django/core/handlers/exception.py", line 41, in inner
    response = get_response(request)
  File "/home/tarena/.local/lib/python3.6/site-packages/django/core/handlers/base.py", line 187, in _get_response
    response = self.process_exception_by_middleware(e, request)
  File "/home/tarena/.local/lib/python3.6/site-packages/django/core/handlers/base.py", line 185, in _get_response
    response = wrapped_callback(request, *callback_args, **callback_kwargs)
  File "/home/tarena/.local/lib/python3.6/site-packages/django/views/generic/base.py", line 68, in view
    return self.dispatch(request, *args, **kwargs)
  File "/home/tarena/.local/lib/python3.6/site-packages/django/views/generic/base.py", line 88, in dispatch
    return handler(request, *args, **kwargs)
  File "/home/tarena/桌面/git/Storage/storage/users/views.py", line 48, in post
    body = json.loads(request.body)
  File "/usr/lib/python3.6/json/__init__.py", line 354, in loads
    return _default_decoder.decode(s)
  File "/usr/lib/python3.6/json/decoder.py", line 339, in decode
    obj, end = self.raw_decode(s, idx=_w(s, 0).end())
  File "/usr/lib/python3.6/json/decoder.py", line 355, in raw_decode
    obj, end = self.scan_once(s, idx)
json.decoder.JSONDecodeError: Invalid control character at: line 3 column 17 (char 31)
[2019-11-18 13:10:30,112] [basehttp.py:124] [basehttp:log_message] [ERROR]- "POST /v1/users/user HTTP/1.1" 500 93410
[2019-11-18 13:11:03,698] [exception.py:135] [exception:handle_uncaught_exception] [ERROR]- Internal Server Error: /v1/users/user
Traceback (most recent call last):
  File "/home/tarena/.local/lib/python3.6/site-packages/django/core/handlers/exception.py", line 41, in inner
    response = get_response(request)
  File "/home/tarena/.local/lib/python3.6/site-packages/django/core/handlers/base.py", line 187, in _get_response
    response = self.process_exception_by_middleware(e, request)
  File "/home/tarena/.local/lib/python3.6/site-packages/django/core/handlers/base.py", line 185, in _get_response
    response = wrapped_callback(request, *callback_args, **callback_kwargs)
  File "/home/tarena/.local/lib/python3.6/site-packages/django/views/generic/base.py", line 68, in view
    return self.dispatch(request, *args, **kwargs)
  File "/home/tarena/.local/lib/python3.6/site-packages/django/views/generic/base.py", line 88, in dispatch
    return handler(request, *args, **kwargs)
  File "/home/tarena/桌面/git/Storage/storage/users/views.py", line 62, in post
    password = hashlib.sha256(password.encode()).update()
TypeError: update() takes exactly 1 argument (0 given)
[2019-11-18 13:11:03,766] [basehttp.py:124] [basehttp:log_message] [ERROR]- "POST /v1/users/user HTTP/1.1" 500 82042
[2019-11-18 13:12:42,447] [exception.py:135] [exception:handle_uncaught_exception] [ERROR]- Internal Server Error: /v1/users/user
Traceback (most recent call last):
  File "/home/tarena/.local/lib/python3.6/site-packages/django/core/handlers/exception.py", line 41, in inner
    response = get_response(request)
  File "/home/tarena/.local/lib/python3.6/site-packages/django/core/handlers/base.py", line 187, in _get_response
    response = self.process_exception_by_middleware(e, request)
  File "/home/tarena/.local/lib/python3.6/site-packages/django/core/handlers/base.py", line 185, in _get_response
    response = wrapped_callback(request, *callback_args, **callback_kwargs)
  File "/home/tarena/.local/lib/python3.6/site-packages/django/views/generic/base.py", line 68, in view
    return self.dispatch(request, *args, **kwargs)
  File "/home/tarena/.local/lib/python3.6/site-packages/django/views/generic/base.py", line 88, in dispatch
    return handler(request, *args, **kwargs)
  File "/home/tarena/桌面/git/Storage/storage/users/views.py", line 66, in post
    password = hashlib.sha256(password.encode()).update()
TypeError: update() takes exactly 1 argument (0 given)
[2019-11-18 13:12:42,535] [basehttp.py:124] [basehttp:log_message] [ERROR]- "POST /v1/users/user HTTP/1.1" 500 82042
[2019-11-18 13:13:34,292] [basehttp.py:124] [basehttp:log_message] [INFO]- "POST /v1/users/user HTTP/1.1" 200 68
[2019-11-18 13:14:07,529] [basehttp.py:124] [basehttp:log_message] [INFO]- "POST /v1/users/user HTTP/1.1" 200 68
[2019-11-18 13:14:52,835] [basehttp.py:124] [basehttp:log_message] [INFO]- "POST /v1/users/user HTTP/1.1" 200 68
[2019-11-18 13:15:16,756] [basehttp.py:124] [basehttp:log_message] [INFO]- "POST /v1/users/user HTTP/1.1" 200 68
[2019-11-18 13:15:33,236] [basehttp.py:124] [basehttp:log_message] [INFO]- "POST /v1/users/user HTTP/1.1" 200 68
[2019-11-18 13:16:14,208] [basehttp.py:124] [basehttp:log_message] [INFO]- "POST /v1/users/user HTTP/1.1" 200 68
[2019-11-18 13:16:23,515] [basehttp.py:124] [basehttp:log_message] [INFO]- "POST /v1/users/user HTTP/1.1" 200 68
[2019-11-18 13:16:33,114] [exception.py:135] [exception:handle_uncaught_exception] [ERROR]- Internal Server Error: /v1/users/user
Traceback (most recent call last):
  File "/home/tarena/.local/lib/python3.6/site-packages/django/core/handlers/exception.py", line 41, in inner
    response = get_response(request)
  File "/home/tarena/.local/lib/python3.6/site-packages/django/core/handlers/base.py", line 187, in _get_response
    response = self.process_exception_by_middleware(e, request)
  File "/home/tarena/.local/lib/python3.6/site-packages/django/core/handlers/base.py", line 185, in _get_response
    response = wrapped_callback(request, *callback_args, **callback_kwargs)
  File "/home/tarena/.local/lib/python3.6/site-packages/django/views/generic/base.py", line 68, in view
    return self.dispatch(request, *args, **kwargs)
  File "/home/tarena/.local/lib/python3.6/site-packages/django/views/generic/base.py", line 88, in dispatch
    return handler(request, *args, **kwargs)
  File "/home/tarena/桌面/git/Storage/storage/users/views.py", line 69, in post
    password = hashlib.sha256(password.encode()).update()
TypeError: update() takes exactly 1 argument (0 given)
[2019-11-18 13:16:33,290] [basehttp.py:124] [basehttp:log_message] [ERROR]- "POST /v1/users/user HTTP/1.1" 500 82037
[2019-11-18 13:17:02,321] [exception.py:135] [exception:handle_uncaught_exception] [ERROR]- Internal Server Error: /v1/users/user
Traceback (most recent call last):
  File "/home/tarena/.local/lib/python3.6/site-packages/django/core/handlers/exception.py", line 41, in inner
    response = get_response(request)
  File "/home/tarena/.local/lib/python3.6/site-packages/django/core/handlers/base.py", line 187, in _get_response
    response = self.process_exception_by_middleware(e, request)
  File "/home/tarena/.local/lib/python3.6/site-packages/django/core/handlers/base.py", line 185, in _get_response
    response = wrapped_callback(request, *callback_args, **callback_kwargs)
  File "/home/tarena/.local/lib/python3.6/site-packages/django/views/generic/base.py", line 68, in view
    return self.dispatch(request, *args, **kwargs)
  File "/home/tarena/.local/lib/python3.6/site-packages/django/views/generic/base.py", line 88, in dispatch
    return handler(request, *args, **kwargs)
  File "/home/tarena/桌面/git/Storage/storage/users/views.py", line 70, in post
    password = hashlib.sha256(password.encode()).update()
TypeError: update() takes exactly 1 argument (0 given)
[2019-11-18 13:17:02,471] [basehttp.py:124] [basehttp:log_message] [ERROR]- "POST /v1/users/user HTTP/1.1" 500 81997
[2019-11-18 13:17:46,899] [exception.py:135] [exception:handle_uncaught_exception] [ERROR]- Internal Server Error: /v1/users/user
Traceback (most recent call last):
  File "/home/tarena/.local/lib/python3.6/site-packages/django/core/handlers/exception.py", line 41, in inner
    response = get_response(request)
  File "/home/tarena/.local/lib/python3.6/site-packages/django/core/handlers/base.py", line 187, in _get_response
    response = self.process_exception_by_middleware(e, request)
  File "/home/tarena/.local/lib/python3.6/site-packages/django/core/handlers/base.py", line 185, in _get_response
    response = wrapped_callback(request, *callback_args, **callback_kwargs)
  File "/home/tarena/.local/lib/python3.6/site-packages/django/views/generic/base.py", line 68, in view
    return self.dispatch(request, *args, **kwargs)
  File "/home/tarena/.local/lib/python3.6/site-packages/django/views/generic/base.py", line 88, in dispatch
    return handler(request, *args, **kwargs)
  File "/home/tarena/桌面/git/Storage/storage/users/views.py", line 68, in post
    hash = hashlib.sha256("你%s好" % (password).encode())
TypeError: Unicode-objects must be encoded before hashing
[2019-11-18 13:17:47,026] [basehttp.py:124] [basehttp:log_message] [ERROR]- "POST /v1/users/user HTTP/1.1" 500 82018
[2019-11-18 13:18:56,623] [views.py:74] [views:post] [ERROR]- 添加失败：(1048, "Column 'password' cannot be null")
[2019-11-18 13:18:56,625] [basehttp.py:124] [basehttp:log_message] [INFO]- "POST /v1/users/user HTTP/1.1" 200 62
[2019-11-18 13:19:12,476] [exception.py:135] [exception:handle_uncaught_exception] [ERROR]- Internal Server Error: /v1/users/user
Traceback (most recent call last):
  File "/home/tarena/.local/lib/python3.6/site-packages/django/core/handlers/exception.py", line 41, in inner
    response = get_response(request)
  File "/home/tarena/.local/lib/python3.6/site-packages/django/core/handlers/base.py", line 187, in _get_response
    response = self.process_exception_by_middleware(e, request)
  File "/home/tarena/.local/lib/python3.6/site-packages/django/core/handlers/base.py", line 185, in _get_response
    response = wrapped_callback(request, *callback_args, **callback_kwargs)
  File "/home/tarena/.local/lib/python3.6/site-packages/django/views/generic/base.py", line 68, in view
    return self.dispatch(request, *args, **kwargs)
  File "/home/tarena/.local/lib/python3.6/site-packages/django/views/generic/base.py", line 88, in dispatch
    return handler(request, *args, **kwargs)
  File "/home/tarena/桌面/git/Storage/storage/users/views.py", line 69, in post
    password = hash.update(password.dencode())
AttributeError: 'str' object has no attribute 'dencode'
[2019-11-18 13:19:12,613] [basehttp.py:124] [basehttp:log_message] [ERROR]- "POST /v1/users/user HTTP/1.1" 500 82277
[2019-11-18 13:19:35,696] [exception.py:135] [exception:handle_uncaught_exception] [ERROR]- Internal Server Error: /v1/users/user
Traceback (most recent call last):
  File "/home/tarena/.local/lib/python3.6/site-packages/django/core/handlers/exception.py", line 41, in inner
    response = get_response(request)
  File "/home/tarena/.local/lib/python3.6/site-packages/django/core/handlers/base.py", line 187, in _get_response
    response = self.process_exception_by_middleware(e, request)
  File "/home/tarena/.local/lib/python3.6/site-packages/django/core/handlers/base.py", line 185, in _get_response
    response = wrapped_callback(request, *callback_args, **callback_kwargs)
  File "/home/tarena/.local/lib/python3.6/site-packages/django/views/generic/base.py", line 68, in view
    return self.dispatch(request, *args, **kwargs)
  File "/home/tarena/.local/lib/python3.6/site-packages/django/views/generic/base.py", line 88, in dispatch
    return handler(request, *args, **kwargs)
  File "/home/tarena/桌面/git/Storage/storage/users/views.py", line 69, in post
    password = hash.update(password).decode()
TypeError: Unicode-objects must be encoded before hashing
[2019-11-18 13:19:35,865] [basehttp.py:124] [basehttp:log_message] [ERROR]- "POST /v1/users/user HTTP/1.1" 500 82207
[2019-11-18 13:19:46,211] [exception.py:135] [exception:handle_uncaught_exception] [ERROR]- Internal Server Error: /v1/users/user
Traceback (most recent call last):
  File "/home/tarena/.local/lib/python3.6/site-packages/django/core/handlers/exception.py", line 41, in inner
    response = get_response(request)
  File "/home/tarena/.local/lib/python3.6/site-packages/django/core/handlers/base.py", line 187, in _get_response
    response = self.process_exception_by_middleware(e, request)
  File "/home/tarena/.local/lib/python3.6/site-packages/django/core/handlers/base.py", line 185, in _get_response
    response = wrapped_callback(request, *callback_args, **callback_kwargs)
  File "/home/tarena/.local/lib/python3.6/site-packages/django/views/generic/base.py", line 68, in view
    return self.dispatch(request, *args, **kwargs)
  File "/home/tarena/.local/lib/python3.6/site-packages/django/views/generic/base.py", line 88, in dispatch
    return handler(request, *args, **kwargs)
  File "/home/tarena/桌面/git/Storage/storage/users/views.py", line 69, in post
    password = hash.update(password)
TypeError: Unicode-objects must be encoded before hashing
[2019-11-18 13:19:46,408] [basehttp.py:124] [basehttp:log_message] [ERROR]- "POST /v1/users/user HTTP/1.1" 500 82189
[2019-11-18 13:20:14,862] [exception.py:135] [exception:handle_uncaught_exception] [ERROR]- Internal Server Error: /v1/users/user
Traceback (most recent call last):
  File "/home/tarena/.local/lib/python3.6/site-packages/django/core/handlers/exception.py", line 41, in inner
    response = get_response(request)
  File "/home/tarena/.local/lib/python3.6/site-packages/django/core/handlers/base.py", line 187, in _get_response
    response = self.process_exception_by_middleware(e, request)
  File "/home/tarena/.local/lib/python3.6/site-packages/django/core/handlers/base.py", line 185, in _get_response
    response = wrapped_callback(request, *callback_args, **callback_kwargs)
  File "/home/tarena/.local/lib/python3.6/site-packages/django/views/generic/base.py", line 68, in view
    return self.dispatch(request, *args, **kwargs)
  File "/home/tarena/.local/lib/python3.6/site-packages/django/views/generic/base.py", line 88, in dispatch
    return handler(request, *args, **kwargs)
  File "/home/tarena/桌面/git/Storage/storage/users/views.py", line 69, in post
    password = hash.update(password.encode())
AttributeError: 'str' object has no attribute 'decode'
[2019-11-18 13:20:15,009] [basehttp.py:124] [basehttp:log_message] [ERROR]- "POST /v1/users/user HTTP/1.1" 500 82271
[2019-11-18 13:21:03,805] [views.py:73] [views:post] [ERROR]- 添加失败：(1048, "Column 'password' cannot be null")
[2019-11-18 13:21:03,808] [basehttp.py:124] [basehttp:log_message] [INFO]- "POST /v1/users/user HTTP/1.1" 200 62
[2019-11-18 13:21:39,686] [exception.py:135] [exception:handle_uncaught_exception] [ERROR]- Internal Server Error: /v1/users/user
Traceback (most recent call last):
  File "/home/tarena/.local/lib/python3.6/site-packages/django/core/handlers/exception.py", line 41, in inner
    response = get_response(request)
  File "/home/tarena/.local/lib/python3.6/site-packages/django/core/handlers/base.py", line 187, in _get_response
    response = self.process_exception_by_middleware(e, request)
  File "/home/tarena/.local/lib/python3.6/site-packages/django/core/handlers/base.py", line 185, in _get_response
    response = wrapped_callback(request, *callback_args, **callback_kwargs)
  File "/home/tarena/.local/lib/python3.6/site-packages/django/views/generic/base.py", line 68, in view
    return self.dispatch(request, *args, **kwargs)
  File "/home/tarena/.local/lib/python3.6/site-packages/django/views/generic/base.py", line 88, in dispatch
    return handler(request, *args, **kwargs)
  File "/home/tarena/桌面/git/Storage/storage/users/views.py", line 69, in post
    print(hash.update(password.encode()))
AttributeError: 'NoneType' object has no attribute 'encode'
[2019-11-18 13:21:39,817] [basehttp.py:124] [basehttp:log_message] [ERROR]- "POST /v1/users/user HTTP/1.1" 500 82086
[2019-11-18 13:21:45,990] [exception.py:135] [exception:handle_uncaught_exception] [ERROR]- Internal Server Error: /v1/users/user
Traceback (most recent call last):
  File "/home/tarena/.local/lib/python3.6/site-packages/django/core/handlers/exception.py", line 41, in inner
    response = get_response(request)
  File "/home/tarena/.local/lib/python3.6/site-packages/django/core/handlers/base.py", line 187, in _get_response
    response = self.process_exception_by_middleware(e, request)
  File "/home/tarena/.local/lib/python3.6/site-packages/django/core/handlers/base.py", line 185, in _get_response
    response = wrapped_callback(request, *callback_args, **callback_kwargs)
  File "/home/tarena/.local/lib/python3.6/site-packages/django/views/generic/base.py", line 68, in view
    return self.dispatch(request, *args, **kwargs)
  File "/home/tarena/.local/lib/python3.6/site-packages/django/views/generic/base.py", line 88, in dispatch
    return handler(request, *args, **kwargs)
  File "/home/tarena/桌面/git/Storage/storage/users/views.py", line 69, in post
    print(hash.update(password.encode()))
AttributeError: 'NoneType' object has no attribute 'encode'
[2019-11-18 13:21:46,076] [basehttp.py:124] [basehttp:log_message] [ERROR]- "POST /v1/users/user HTTP/1.1" 500 82086
[2019-11-18 13:21:50,495] [exception.py:135] [exception:handle_uncaught_exception] [ERROR]- Internal Server Error: /v1/users/user
Traceback (most recent call last):
  File "/home/tarena/.local/lib/python3.6/site-packages/django/core/handlers/exception.py", line 41, in inner
    response = get_response(request)
  File "/home/tarena/.local/lib/python3.6/site-packages/django/core/handlers/base.py", line 187, in _get_response
    response = self.process_exception_by_middleware(e, request)
  File "/home/tarena/.local/lib/python3.6/site-packages/django/core/handlers/base.py", line 185, in _get_response
    response = wrapped_callback(request, *callback_args, **callback_kwargs)
  File "/home/tarena/.local/lib/python3.6/site-packages/django/views/generic/base.py", line 68, in view
    return self.dispatch(request, *args, **kwargs)
  File "/home/tarena/.local/lib/python3.6/site-packages/django/views/generic/base.py", line 88, in dispatch
    return handler(request, *args, **kwargs)
  File "/home/tarena/桌面/git/Storage/storage/users/views.py", line 69, in post
    print(hash.update(password.encode()))
AttributeError: 'NoneType' object has no attribute 'encode'
[2019-11-18 13:21:50,572] [basehttp.py:124] [basehttp:log_message] [ERROR]- "POST /v1/users/user HTTP/1.1" 500 82086
[2019-11-18 13:22:01,934] [exception.py:135] [exception:handle_uncaught_exception] [ERROR]- Internal Server Error: /v1/users/user
Traceback (most recent call last):
  File "/home/tarena/.local/lib/python3.6/site-packages/django/core/handlers/exception.py", line 41, in inner
    response = get_response(request)
  File "/home/tarena/.local/lib/python3.6/site-packages/django/core/handlers/base.py", line 187, in _get_response
    response = self.process_exception_by_middleware(e, request)
  File "/home/tarena/.local/lib/python3.6/site-packages/django/core/handlers/base.py", line 185, in _get_response
    response = wrapped_callback(request, *callback_args, **callback_kwargs)
  File "/home/tarena/.local/lib/python3.6/site-packages/django/views/generic/base.py", line 68, in view
    return self.dispatch(request, *args, **kwargs)
  File "/home/tarena/.local/lib/python3.6/site-packages/django/views/generic/base.py", line 88, in dispatch
    return handler(request, *args, **kwargs)
  File "/home/tarena/桌面/git/Storage/storage/users/views.py", line 70, in post
    print(hash.update(password.encode()))
AttributeError: 'NoneType' object has no attribute 'encode'
[2019-11-18 13:22:02,060] [basehttp.py:124] [basehttp:log_message] [ERROR]- "POST /v1/users/user HTTP/1.1" 500 82095
[2019-11-18 13:22:30,672] [exception.py:135] [exception:handle_uncaught_exception] [ERROR]- Internal Server Error: /v1/users/user
Traceback (most recent call last):
  File "/home/tarena/.local/lib/python3.6/site-packages/django/core/handlers/exception.py", line 41, in inner
    response = get_response(request)
  File "/home/tarena/.local/lib/python3.6/site-packages/django/core/handlers/base.py", line 187, in _get_response
    response = self.process_exception_by_middleware(e, request)
  File "/home/tarena/.local/lib/python3.6/site-packages/django/core/handlers/base.py", line 185, in _get_response
    response = wrapped_callback(request, *callback_args, **callback_kwargs)
  File "/home/tarena/.local/lib/python3.6/site-packages/django/views/generic/base.py", line 68, in view
    return self.dispatch(request, *args, **kwargs)
  File "/home/tarena/.local/lib/python3.6/site-packages/django/views/generic/base.py", line 88, in dispatch
    return handler(request, *args, **kwargs)
  File "/home/tarena/桌面/git/Storage/storage/users/views.py", line 70, in post
    print(hash.update(password.encode()))
AttributeError: 'NoneType' object has no attribute 'encode'
[2019-11-18 13:22:30,861] [basehttp.py:124] [basehttp:log_message] [ERROR]- "POST /v1/users/user HTTP/1.1" 500 82095
[2019-11-18 13:22:51,709] [views.py:74] [views:post] [ERROR]- 添加失败：(1048, "Column 'password' cannot be null")
[2019-11-18 13:22:51,713] [basehttp.py:124] [basehttp:log_message] [INFO]- "POST /v1/users/user HTTP/1.1" 200 62
[2019-11-18 13:22:54,509] [views.py:74] [views:post] [ERROR]- 添加失败：(1048, "Column 'password' cannot be null")
[2019-11-18 13:22:54,512] [basehttp.py:124] [basehttp:log_message] [INFO]- "POST /v1/users/user HTTP/1.1" 200 62
[2019-11-18 13:22:58,572] [views.py:74] [views:post] [ERROR]- 添加失败：(1048, "Column 'password' cannot be null")
[2019-11-18 13:22:58,576] [basehttp.py:124] [basehttp:log_message] [INFO]- "POST /v1/users/user HTTP/1.1" 200 62
[2019-11-18 13:23:17,855] [views.py:75] [views:post] [ERROR]- 添加失败：(1048, "Column 'password' cannot be null")
[2019-11-18 13:23:17,858] [basehttp.py:124] [basehttp:log_message] [INFO]- "POST /v1/users/user HTTP/1.1" 200 62
[2019-11-18 13:23:46,817] [basehttp.py:124] [basehttp:log_message] [INFO]- "POST /v1/users/user HTTP/1.1" 200 13
[2019-11-18 13:24:09,143] [basehttp.py:124] [basehttp:log_message] [INFO]- "POST /v1/users/user HTTP/1.1" 200 80
[2019-11-18 13:24:20,845] [basehttp.py:124] [basehttp:log_message] [INFO]- "POST /v1/users/user HTTP/1.1" 200 13
[2019-11-18 13:26:18,892] [basehttp.py:124] [basehttp:log_message] [INFO]- "POST /v1/users/user HTTP/1.1" 200 80
[2019-11-18 13:26:24,817] [basehttp.py:124] [basehttp:log_message] [INFO]- "POST /v1/users/user HTTP/1.1" 200 13
[2019-11-18 13:26:45,828] [basehttp.py:124] [basehttp:log_message] [INFO]- "GET /v1/users/user?page=1 HTTP/1.1" 200 1107
[2019-11-18 13:26:46,960] [basehttp.py:124] [basehttp:log_message] [INFO]- "OPTIONS /v1/users/user?page=3 HTTP/1.1" 200 0
[2019-11-18 13:26:46,975] [basehttp.py:124] [basehttp:log_message] [INFO]- "GET /v1/users/user?page=3 HTTP/1.1" 200 304
